Workbook

Sheet Data_Sheet
A1: Player Name | B1: Salary | C1: Position | D1: Age | E1: Team | F1: GP | G1: GS | H1: MP | I1: FG | J1: FGA | K1: FG% | L1: 3P | M1: 3PA | N1: 3P% | O1: 2P | P1: 2PA | Q1: 2P% | R1: eFG% | S1: FT | T1: FTA | U1: FT% | V1: ORB | W1: DRB | X1: TRB | Y1: AST | Z1: STL | AA1: BLK | AB1: TOV | AC1: PF | AD1: PTS | AE1: Total Minutes | AF1: PER | AG1: TS% | AH1: 3PAr | AI1: FTr | AJ1: ORB% | AK1: DRB% | AL1: TRB% | AM1: AST% | AN1: STL% | AO1: BLK% | AP1: TOV% | AQ1: USG% | AR1: OWS | AS1: DWS | AT1: WS | AU1: WS/48 | AV1: OBPM | AW1: DBPM | AX1: BPM | AY1: VORP | AZ1: Score | BA1: Score_per_$M
A2: Stephen Curry | B2: 48070014 | C2: PG | D2: 34 | E2: GSW | F2: 56 | G2: 56 | H2: 34.7 | I2: 10 | J2: 20.2 | K2: 0.493 | L2: 4.9 | M2: 11.4 | N2: 0.427 | O2: 5.1 | P2: 8.8 | Q2: 0.579 | R2: 0.614 | S2: 4.6 | T2: 5 | U2: 0.915 | V2: 0.7 | W2: 5.4 | X2: 6.1 | Y2: 6.3 | Z2: 0.9 | AA2: 0.4 | AB2: 3.2 | AC2: 2.1 | AD2: 29.4 | AE2: 1941 | AF2: 24.1 | AG2: 0.656 | AH2: 0.564 | AI2: 0.248 | AJ2: 2.3 | AK2: 16.8 | AL2: 9.7 | AM2: 30 | AN2: 1.3 | AO2: 0.9 | AP2: 12.5 | AQ2: 31 | AR2: 5.8 | AS2: 2 | AT2: 7.8 | AU2: 0.192 | AV2: 7.5 | AW2: 0.1 | AX2: 7.5 | AY2: 4.7 | AZ2: =0.5*AX2 + 0.5*AT2 -> 7.65 | BA2: =IF(B2>0, AZ2*1000000/B2, 0) -> 0.15914287
A3: John Wall | B3: 47345760 | C3: PG | D3: 32 | E3: LAC | F3: 34 | G3: 3 | H3: 22.2 | I3: 4.1 | J3: 9.9 | K3: 0.408 | L3: 1 | M3: 3.2 | N3: 0.303 | O3: 3.1 | P3: 6.7 | Q3: 0.459 | R3: 0.457 | S3: 2.3 | T3: 3.3 | U3: 0.681 | V3: 0.4 | W3: 2.3 | X3: 2.7 | Y3: 5.2 | Z3: 0.8 | AA3: 0.4 | AB3: 2.4 | AC3: 1.7 | AD3: 11.4 | AE3: 755 | AF3: 13.6 | AG3: 0.498 | AH3: 0.322 | AI3: 0.334 | AJ3: 2.1 | AK3: 11.4 | AL3: 6.8 | AM3: 35.3 | AN3: 1.8 | AO3: 1.4 | AP3: 17.1 | AQ3: 27 | AR3: -0.4 | AS3: 0.7 | AT3: 0.3 | AU3: 0.02 | AV3: -0.8 | AW3: -0.4 | AX3: -1.2 | AY3: 0.1 | AZ3: =0.5*AX3 + 0.5*AT3 -> -0.45 | BA3: =IF(B3>0, AZ3*1000000/B3, 0) -> -0.009504547
A4: Russell Westbrook | B4: 47080179 | C4: PG | D4: 34 | E4: LAC | F4: 73 | G4: 24 | H4: 29.1 | I4: 5.9 | J4: 13.6 | K4: 0.436 | L4: 1.2 | M4: 3.9 | N4: 0.311 | O4: 4.7 | P4: 9.7 | Q4: 0.487 | R4: 0.481 | S4: 2.8 | T4: 4.3 | U4: 0.656 | V4: 1.2 | W4: 4.6 | X4: 5.8 | Y4: 7.5 | Z4: 1 | AA4: 0.5 | AB4: 3.5 | AC4: 2.2 | AD4: 15.9 | AE4: 2126 | AF4: 16.1 | AG4: 0.513 | AH4: 0.289 | AI4: 0.317 | AJ4: 4.7 | AK4: 16.5 | AL4: 10.8 | AM4: 38.6 | AN4: 1.7 | AO4: 1.3 | AP4: 18.4 | AQ4: 27.7 | AR4: -0.6 | AS4: 2.6 | AT4: 1.9 | AU4: 0.044 | AV4: 0.3 | AW4: -0.1 | AX4: 0.2 | AY4: 1.2 | AZ4: =0.5*AX4 + 0.5*AT4 -> 1.05 | BA4: =IF(B4>0, AZ4*1000000/B4, 0) -> 0.022302379
A5: LeBron James | B5: 44474988 | C5: PF | D5: 38 | E5: LAL | F5: 55 | G5: 54 | H5: 35.5 | I5: 11.1 | J5: 22.2 | K5: 0.5 | L5: 2.2 | M5: 6.9 | N5: 0.321 | O5: 8.9 | P5: 15.3 | Q5: 0.58 | R5: 0.549 | S5: 4.6 | T5: 5.9 | U5: 0.768 | V5: 1.2 | W5: 7.1 | X5: 8.3 | Y5: 6.8 | Z5: 0.9 | AA5: 0.6 | AB5: 3.2 | AC5: 1.6 | AD5: 28.9 | AE5: 1954 | AF5: 23.9 | AG5: 0.583 | AH5: 0.309 | AI5: 0.268 | AJ5: 3.7 | AK5: 20.8 | AL5: 12.5 | AM5: 33.5 | AN5: 1.2 | AO5: 1.4 | AP5: 11.6 | AQ5: 33.3 | AR5: 3.2 | AS5: 2.4 | AT5: 5.6 | AU5: 0.138 | AV5: 5.5 | AW5: 0.6 | AX5: 6.1 | AY5: 4 | AZ5: =0.5*AX5 + 0.5*AT5 -> 5.85 | BA5: =IF(B5>0, AZ5*1000000/B5, 0) -> 0.13153461
A6: Kevin Durant | B6: 44119845 | C6: PF | D6: 34 | E6: PHO | F6: 47 | G6: 47 | H6: 35.6 | I6: 10.3 | J6: 18.3 | K6: 0.56 | L6: 2 | M6: 4.9 | N6: 0.404 | O6: 8.3 | P6: 13.4 | Q6: 0.617 | R6: 0.614 | S6: 6.5 | T6: 7.1 | U6: 0.919 | V6: 0.4 | W6: 6.3 | X6: 6.7 | Y6: 5 | Z6: 0.7 | AA6: 1.4 | AB6: 3.3 | AC6: 2.1 | AD6: 29.1 | AE6: 1672 | AF6: 25.9 | AG6: 0.677 | AH6: 0.267 | AI6: 0.387 | AJ6: 1.2 | AK6: 19.5 | AL6: 10.5 | AM6: 24.5 | AN6: 1 | AO6: 3.4 | AP6: 13.4 | AQ6: 30.7 | AR6: 4.7 | AS6: 2.1 | AT6: 6.8 | AU6: 0.194 | AV6: 6 | AW6: 1.2 | AX6: 7.1 | AY6: 3.9 | AZ6: =0.5*AX6 + 0.5*AT6 -> 6.95 | BA6: =IF(B6>0, AZ6*1000000/B6, 0) -> 0.15752549
A7: Bradley Beal | B7: 43279250 | C7: SG | D7: 29 | E7: WAS | F7: 50 | G7: 50 | H7: 33.5 | I7: 8.9 | J7: 17.6 | K7: 0.506 | L7: 1.6 | M7: 4.4 | N7: 0.365 | O7: 7.3 | P7: 13.2 | Q7: 0.552 | R7: 0.551 | S7: 3.8 | T7: 4.6 | U7: 0.842 | V7: 0.8 | W7: 3.1 | X7: 3.9 | Y7: 5.4 | Z7: 0.9 | AA7: 0.7 | AB7: 2.9 | AC7: 2.1 | AD7: 23.2 | AE7: 1673 | AF7: 19.7 | AG7: 0.593 | AH7: 0.249 | AI7: 0.26 | AJ7: 2.8 | AK7: 9.9 | AL7: 6.5 | AM7: 26.6 | AN7: 1.3 | AO7: 1.7 | AP7: 12.9 | AQ7: 29.2 | AR7: 2.2 | AS7: 1.2 | AT7: 3.4 | AU7: 0.099 | AV7: 2.9 | AW7: -1.2 | AX7: 1.8 | AY7: 1.6 | AZ7: =0.5*AX7 + 0.5*AT7 -> 2.6 | BA7: =IF(B7>0, AZ7*1000000/B7, 0) -> 0.060074978
A8: Kawhi Leonard | B8: 42492492 | C8: SF | D8: 31 | E8: LAC | F8: 52 | G8: 50 | H8: 33.6 | I8: 8.6 | J8: 16.8 | K8: 0.512 | L8: 2 | M8: 4.8 | N8: 0.416 | O8: 6.6 | P8: 11.9 | Q8: 0.551 | R8: 0.572 | S8: 4.7 | T8: 5.4 | U8: 0.871 | V8: 1.1 | W8: 5.4 | X8: 6.5 | Y8: 3.9 | Z8: 1.4 | AA8: 0.5 | AB8: 1.7 | AC8: 1.6 | AD8: 23.8 | AE8: 1748 | AF8: 23.9 | AG8: 0.623 | AH8: 0.287 | AI8: 0.32 | AJ8: 3.7 | AK8: 17.8 | AL8: 10.8 | AM8: 19.6 | AN8: 2 | AO8: 1.4 | AP8: 8.1 | AQ8: 27 | AR8: 4.9 | AS8: 2.2 | AT8: 7.1 | AU8: 0.194 | AV8: 5.1 | AW8: 0.9 | AX8: 6.1 | AY8: 3.5 | AZ8: =0.5*AX8 + 0.5*AT8 -> 6.6 | BA8: =IF(B8>0, AZ8*1000000/B8, 0) -> 0.15532156
A9: Paul George | B9: 42492492 | C9: SF | D9: 32 | E9: LAC | F9: 56 | G9: 56 | H9: 34.6 | I9: 8.2 | J9: 17.9 | K9: 0.457 | L9: 2.8 | M9: 7.6 | N9: 0.371 | O9: 5.4 | P9: 10.3 | Q9: 0.521 | R9: 0.536 | S9: 4.6 | T9: 5.3 | U9: 0.871 | V9: 0.8 | W9: 5.3 | X9: 6.1 | Y9: 5.1 | Z9: 1.5 | AA9: 0.4 | AB9: 3.1 | AC9: 2.8 | AD9: 23.8 | AE9: 1939 | AF9: 19.6 | AG9: 0.588 | AH9: 0.424 | AI9: 0.293 | AJ9: 2.6 | AK9: 17 | AL9: 9.9 | AM9: 24.2 | AN9: 2.1 | AO9: 0.9 | AP9: 13.4 | AQ9: 29.5 | AR9: 2.3 | AS9: 2.3 | AT9: 4.6 | AU9: 0.114 | AV9: 2.4 | AW9: 0.3 | AX9: 2.8 | AY9: 2.3 | AZ9: =0.5*AX9 + 0.5*AT9 -> 3.7 | BA9: =IF(B9>0, AZ9*1000000/B9, 0) -> 0.087074206
A10: Giannis Antetokounmpo | B10: 42492492 | C10: PF | D10: 28 | E10: MIL | F10: 63 | G10: 63 | H10: 32.1 | I10: 11.2 | J10: 20.3 | K10: 0.553 | L10: 0.7 | M10: 2.7 | N10: 0.275 | O10: 10.5 | P10: 17.6 | Q10: 0.596 | R10: 0.572 | S10: 7.9 | T10: 12.3 | U10: 0.645 | V10: 2.2 | W10: 9.6 | X10: 11.8 | Y10: 5.7 | Z10: 0.8 | AA10: 0.8 | AB10: 3.9 | AC10: 3.1 | AD10: 31.1 | AE10: 2024 | AF10: 29 | AG10: 0.605 | AH10: 0.134 | AI10: 0.604 | AJ10: 7.3 | AK10: 30 | AL10: 19.1 | AM10: 33.2 | AN10: 1.2 | AO10: 2.1 | AP10: 13.2 | AQ10: 38.8 | AR10: 4.9 | AS10: 3.7 | AT10: 8.6 | AU10: 0.204 | AV10: 5.8 | AW10: 2.7 | AX10: 8.5 | AY10: 5.4 | AZ10: =0.5*AX10 + 0.5*AT10 -> 8.55 | BA10: =IF(B10>0, AZ10*1000000/B10, 0) -> 0.20121202
A11: Damian Lillard | B11: 42492492 | C11: PG | D11: 32 | E11: POR | F11: 58 | G11: 58 | H11: 36.3 | I11: 9.6 | J11: 20.7 | K11: 0.463 | L11: 4.2 | M11: 11.3 | N11: 0.371 | O11: 5.4 | P11: 9.4 | Q11: 0.574 | R11: 0.564 | S11: 8.8 | T11: 9.6 | U11: 0.914 | V11: 0.8 | W11: 4 | X11: 4.8 | Y11: 7.3 | Z11: 0.9 | AA11: 0.3 | AB11: 3.3 | AC11: 1.9 | AD11: 32.2 | AE11: 2107 | AF11: 26.7 | AG11: 0.645 | AH11: 0.547 | AI11: 0.464 | AJ11: 2.4 | AK11: 12.8 | AL11: 7.6 | AM11: 35 | AN11: 1.2 | AO11: 0.8 | AP11: 11.7 | AQ11: 33.8 | AR11: 8.2 | AS11: 0.8 | AT11: 9 | AU11: 0.205 | AV11: 8.3 | AW11: -1.2 | AX11: 7.1 | AY11: 4.9 | AZ11: =0.5*AX11 + 0.5*AT11 -> 8.05 | BA11: =IF(B11>0, AZ11*1000000/B11, 0) -> 0.18944523
A12: Klay Thompson | B12: 40600080 | C12: SF | D12: 32 | E12: GSW | F12: 69 | G12: 69 | H12: 33 | I12: 7.9 | J12: 18.1 | K12: 0.436 | L12: 4.4 | M12: 10.6 | N12: 0.412 | O12: 3.6 | P12: 7.6 | Q12: 0.47 | R12: 0.556 | S12: 1.7 | T12: 1.9 | U12: 0.879 | V12: 0.6 | W12: 3.6 | X12: 4.1 | Y12: 2.4 | Z12: 0.7 | AA12: 0.4 | AB12: 1.8 | AC12: 1.9 | AD12: 21.9 | AE12: 2279 | AF12: 14.7 | AG12: 0.576 | AH12: 0.584 | AI12: 0.105 | AJ12: 1.9 | AK12: 11.7 | AL12: 6.9 | AM12: 11 | AN12: 1 | AO12: 1.1 | AP12: 8.6 | AQ12: 26.4 | AR12: 1.2 | AS12: 1.9 | AT12: 3.1 | AU12: 0.066 | AV12: 1.5 | AW12: -1.7 | AX12: -0.3 | AY12: 1 | AZ12: =0.5*AX12 + 0.5*AT12 -> 1.4 | BA12: =IF(B12>0, AZ12*1000000/B12, 0) -> 0.034482691
A13: Kyrie Irving | B13: 38917057 | C13: SG | D13: 30 | E13: DAL | F13: 60 | G13: 60 | H13: 37.4 | I13: 9.9 | J13: 20.1 | K13: 0.494 | L13: 3.1 | M13: 8.3 | N13: 0.379 | O13: 6.8 | P13: 11.8 | Q13: 0.574 | R13: 0.572 | S13: 4.1 | T13: 4.6 | U13: 0.905 | V13: 1 | W13: 4.1 | X13: 5.1 | Y13: 5.5 | Z13: 1.1 | AA13: 0.8 | AB13: 2.1 | AC13: 2.8 | AD13: 27.1 | AE13: 2241 | AF13: 22.4 | AG13: 0.613 | AH13: 0.412 | AI13: 0.227 | AJ13: 3 | AK13: 12.3 | AL13: 7.7 | AM13: 25.4 | AN13: 1.4 | AO13: 1.7 | AP13: 8.8 | AQ13: 28.9 | AR13: 5.4 | AS13: 2 | AT13: 7.4 | AU13: 0.159 | AV13: 4.8 | AW13: -0.7 | AX13: 4.1 | AY13: 3.5 | AZ13: =0.5*AX13 + 0.5*AT13 -> 5.75 | BA13: =IF(B13>0, AZ13*1000000/B13, 0) -> 0.14775012
... A76: Dejounte Murray | B76: 17071120 | C76: SG | D76: 26 | E76: ATL | F76: 74 | G76: 74 | H76: 36.4 | I76: 8.3 | J76: 17.8 | K76: 0.464 | L76: 1.8 | M76: 5.2 | N76: 0.344 | O76: 6.5 | P76: 12.6 | Q76: 0.514 | R76: 0.514 | S76: 2.1 | T76: 2.6 | U76: 0.832 | V76: 0.7 | W76: 4.5 | X76: 5.3 | Y76: 6.1 | Z76: 1.5 | AA76: 0.3 | AB76: 2.2 | AC76: 1.4 | AD76: 20.5 | AE76: 2693 | AF76: 17 | AG76: 0.54 | AH76: 0.293 | AI76: 0.144 | AJ76: 2.1 | AK76: 13.8 | AL76: 7.9 | AM76: 24 | AN76: 2 | AO76: 0.6 | AP76: 10.2 | AQ76: 24.4 | AR76: 2.4 | AS76: 2.3 | AT76: 4.7 | AU76: 0.084 | AV76: 1.1 | AW76: 0 | AX76: 1 | AY76: 2.1 | AZ76: =0.5*AX76 + 0.5*AT76 -> 2.85 | BA76: =IF(B76>0, AZ76*1000000/B76, 0) -> 0.16694862
A77: Mitchell Robinson | B77: 17045454 | C77: C | D77: 24 | E77: NYK | F77: 59 | G77: 58 | H77: 27 | I77: 3.2 | J77: 4.7 | K77: 0.671 | L77: 0 | M77: 0 | O77: 3.2 | P77: 4.7 | Q77: 0.671 | R77: 0.671 | S77: 1 | T77: 2.1 | U77: 0.484 | V77: 4.5 | W77: 4.9 | X77: 9.4 | Y77: 0.9 | Z77: 0.9 | AA77: 1.8 | AB77: 0.7 | AC77: 2.7 | AD77: 7.4 | AE77: 1591 | AF77: 18.9 | AG77: 0.652 | AH77: 0 | AI77: 0.436 | AJ77: 18.4 | AK77: 20 | AL77: 19.2 | AM77: 4.5 | AN77: 1.7 | AO77: 6.5 | AP77: 10.9 | AQ77: 10.1 | AR77: 4 | AS77: 2.6 | AT77: 6.5 | AU77: 0.197 | AV77: 1 | AW77: 1.4 | AX77: 2.4 | AY77: 1.7 | AZ77: =0.5*AX77 + 0.5*AT77 -> 4.45 | BA77: =IF(B77>0, AZ77*1000000/B77, 0) -> 0.26106668
A78: Duncan Robinson | B78: 16902000 | C78: SF | D78: 28 | E78: MIA | F78: 42 | G78: 1 | H78: 16.5 | I78: 2.1 | J78: 5.6 | K78: 0.371 | L78: 1.5 | M78: 4.6 | N78: 0.328 | O78: 0.6 | P78: 1.1 | Q78: 0.556 | R78: 0.504 | S78: 0.7 | T78: 0.8 | U78: 0.906 | V78: 0.2 | W78: 1.5 | X78: 1.6 | Y78: 1.1 | Z78: 0.3 | AA78: 0 | AB78: 0.7 | AC78: 1.8 | AD78: 6.4 | AE78: 691 | AF78: 7.8 | AG78: 0.534 | AH78: 0.81 | AI78: 0.135 | AJ78: 1.3 | AK78: 10.7 | AL78: 5.9 | AM78: 9.7 | AN78: 1 | AO78: 0 | AP78: 10 | AQ78: 17.9 | AR78: -0.1 | AS78: 0.6 | AT78: 0.5 | AU78: 0.035 | AV78: -3.5 | AW78: -1.5 | AX78: -5 | AY78: -0.5 | AZ78: =0.5*AX78 + 0.5*AT78 -> -2.25 | BA78: =IF(B78>0, AZ78*1000000/B78, 0) -> -0.13312034
A79: Norman Powell | B79: 16758621 | C79: SG | D79: 29 | E79: LAC | F79: 60 | G79: 8 | H79: 26.1 | I79: 5.7 | J79: 11.8 | K79: 0.479 | L79: 1.9 | M79: 4.8 | N79: 0.397 | O79: 3.8 | P79: 7.1 | Q79: 0.534 | R79: 0.559 | S79: 3.8 | T79: 4.6 | U79: 0.812 | V79: 0.4 | W79: 2.5 | X79: 2.9 | Y79: 1.8 | Z79: 0.8 | AA79: 0.3 | AB79: 1.7 | AC79: 2.1 | AD79: 17 | AE79: 1567 | AF79: 17.1 | AG79: 0.612 | AH79: 0.404 | AI79: 0.39 | AJ79: 1.7 | AK79: 10.7 | AL79: 6.3 | AM79: 11 | AN79: 1.6 | AO79: 1 | AP79: 10.8 | AQ79: 26 | AR79: 2.1 | AS79: 1.4 | AT79: 3.5 | AU79: 0.107 | AV79: 0.9 | AW79: -0.7 | AX79: 0.3 | AY79: 0.9 | AZ79: =0.5*AX79 + 0.5*AT79 -> 1.9 | BA79: =IF(B79>0, AZ79*1000000/B79, 0) -> 0.11337448
A80: Collin Sexton | B80: 16700000 | C80: PG | D80: 24 | E80: UTA | F80: 48 | G80: 15 | H80: 23.9 | I80: 4.9 | J80: 9.8 | K80: 0.506 | L80: 1 | M80: 2.5 | N80: 0.393 | O80: 3.9 | P80: 7.2 | Q80: 0.546 | R80: 0.558 | S80: 3.4 | T80: 4.1 | U80: 0.819 | V80: 0.8 | W80: 1.4 | X80: 2.2 | Y80: 2.9 | Z80: 0.6 | AA80: 0.1 | AB80: 1.8 | AC80: 2.3 | AD80: 14.3 | AE80: 1145 | AF80: 15.9 | AG80: 0.616 | AH80: 0.261 | AI80: 0.425 | AJ80: 3.5 | AK80: 6.3 | AL80: 5 | AM80: 17.9 | AN80: 1.1 | AO80: 0.4 | AP80: 13.3 | AQ80: 23.4 | AR80: 2 | AS80: 0.5 | AT80: 2.5 | AU80: 0.105 | AV80: 0.1 | AW80: -1.5 | AX80: -1.3 | AY80: 0.2 | AZ80: =0.5*AX80 + 0.5*AT80 -> 0.6 | BA80: =IF(B80>0, AZ80*1000000/B80, 0) -> 0.035928144
A81: Markelle Fultz | B81: 16500000 | C81: PG | D81: 24 | E81: ORL | F81: 60 | G81: 60 | H81: 29.6 | I81: 5.8 | J81: 11.3 | K81: 0.514 | L81: 0.5 | M81: 1.5 | N81: 0.31 | O81: 5.4 | P81: 9.9 | Q81: 0.544 | R81: 0.534 | S81: 1.9 | T81: 2.4 | U81: 0.783 | V81: 1.2 | W81: 2.8 | X81: 3.9 | Y81: 5.7 | Z81: 1.5 | AA81: 0.4 | AB81: 2.3 | AC81: 2.2 | AD81: 14 | AE81: 1778 | AF81: 16.6 | AG81: 0.564 | AH81: 0.128 | AI81: 0.211 | AJ81: 4.4 | AK81: 10.5 | AL81: 7.4 | AM81: 29.8 | AN81: 2.4 | AO81: 1.4 | AP81: 15.8 | AQ81: 21.3 | AR81: 1.7 | AS81: 2 | AT81: 3.7 | AU81: 0.1 | AV81: -0.1 | AW81: 0.7 | AX81: 0.5 | AY81: 1.2 | AZ81: =0.5*AX81 + 0.5*AT81 -> 2.1 | BA81: =IF(B81>0, AZ81*1000000/B81, 0) -> 0.12727273
A82: Lauri Markkanen | B82: 16475454 | C82: PF | D82: 25 | E82: UTA | F82: 66 | G82: 66 | H82: 34.4 | I82: 8.7 | J82: 17.3 | K82: 0.499 | L82: 3 | M82: 7.7 | N82: 0.391 | O82: 5.6 | P82: 9.6 | Q82: 0.585 | R82: 0.586 | S82: 5.3 | T82: 6 | U82: 0.875 | V82: 2 | W82: 6.7 | X82: 8.6 | Y82: 1.9 | Z82: 0.6 | AA82: 0.6 | AB82: 1.9 | AC82: 2.1 | AD82: 25.6 | AE82: 2273 | AF82: 22.1 | AG82: 0.64 | AH82: 0.446 | AI82: 0.348 | AJ82: 6.3 | AK82: 20.7 | AL82: 13.6 | AM82: 8.6 | AN82: 0.9 | AO82: 1.4 | AP82: 8.8 | AQ82: 26.6 | AR82: 6.3 | AS82: 1.9 | AT82: 8.2 | AU82: 0.173 | AV82: 4.9 | AW82: -1 | AX82: 3.8 | AY82: 3.3 | AZ82: =0.5*AX82 + 0.5*AT82 -> 6 | BA82: =IF(B82>0, AZ82*1000000/B82, 0) -> 0.36417813
A83: Marcus Morris | B83: 16372093 | C83: PF | D83: 33 | E83: LAC | F83: 65 | G83: 65 | H83: 28.1 | I83: 4.2 | J83: 9.9 | K83: 0.426 | L83: 1.7 | M83: 4.7 | N83: 0.364 | O83: 2.5 | P83: 5.2 | Q83: 0.484 | R83: 0.513 | S83: 1 | T83: 1.3 | U83: 0.782 | V83: 0.4 | W83: 3.5 | X83: 4 | Y83: 1.8 | Z83: 0.6 | AA83: 0.3 | AB83: 0.9 | AC83: 2.1 | AD83: 11.2 | AE83: 1825 | AF83: 10.5 | AG83: 0.534 | AH83: 0.479 | AI83: 0.135 | AJ83: 1.8 | AK83: 13.9 | AL83: 7.9 | AM83: 8.9 | AN83: 1.1 | AO83: 1 | AP83: 7.6 | AQ83: 17.6 | AR83: 0.4 | AS83: 1.6 | AT83: 2 | AU83: 0.053 | AV83: -1.8 | AW83: -0.2 | AX83: -1.9 | AY83: 0 | AZ83: =0.5*AX83 + 0.5*AT83 -> 0.05 | BA83: =IF(B83>0, AZ83*1000000/B83, 0) -> 0.0030539773
A84: Malik Beasley | B84: 15558035 | C84: SG | D84: 26 | E84: UTA | F84: 81 | G84: 27 | H84: 25.8 | I84: 4.6 | J84: 11.6 | K84: 0.395 | L84: 2.9 | M84: 8.1 | N84: 0.357 | O84: 1.7 | P84: 3.4 | Q84: 0.484 | R84: 0.52 | S84: 0.6 | T84: 0.8 | U84: 0.769 | V84: 0.4 | W84: 3.1 | X84: 3.5 | Y84: 1.5 | Z84: 0.8 | AA84: 0.1 | AB84: 1.1 | AC84: 1.3 | AD84: 12.7 | AE84: 2093 | AF84: 10.9 | AG84: 0.531 | AH84: 0.702 | AI84: 0.069 | AJ84: 1.8 | AK84: 12.5 | AL84: 7.3 | AM84: 8.4 | AN84: 1.5 | AO84: 0.4 | AP84: 8.5 | AQ84: 21.1 | AR84: -0.2 | AS84: 1.6 | AT84: 1.4 | AU84: 0.032 | AV84: -0.9 | AW84: -1 | AX84: -2 | AY84: 0 | AZ84: =0.5*AX84 + 0.5*AT84 -> -0.3 | BA84: =IF(B84>0, AZ84*1000000/B84, 0) -> -0.019282641
A85: Luguentz Dort | B85: 15277778 | C85: SF | D85: 23 | E85: OKC | F85: 74 | G85: 73 | H85: 30.7 | I85: 4.6 | J85: 11.8 | K85: 0.388 | L85: 1.8 | M85: 5.5 | N85: 0.33 | O85: 2.8 | P85: 6.3 | Q85: 0.44 | R85: 0.466 | S85: 2.7 | T85: 3.5 | U85: 0.772 | V85: 1.7 | W85: 2.9 | X85: 4.6 | Y85: 2.1 | Z85: 1 | AA85: 0.3 | AB85: 1.2 | AC85: 3.3 | AD85: 13.7 | AE85: 2272 | AF85: 11.3 | AG85: 0.513 | AH85: 0.468 | AI85: 0.297 | AJ85: 5.9 | AK85: 10.4 | AL85: 8.1 | AM85: 9.2 | AN85: 1.6 | AO85: 0.9 | AP85: 8.5 | AQ85: 19.8 | AR85: 0.9 | AS85: 2.1 | AT85: 2.9 | AU85: 0.062 | AV85: -2 | AW85: -1 | AX85: -3 | AY85: -0.6 | AZ85: =0.5*AX85 + 0.5*AT85 -> -0.05 | BA85: =IF(B85>0, AZ85*1000000/B85, 0) -> -0.0032727272
A86: Will Barton | B86: 15059712 | C86: SG | D86: 32 | E86: TOR | F86: 56 | G86: 2 | H86: 17.7 | I86: 2.5 | J86: 6.5 | K86: 0.379 | L86: 1.2 | M86: 3.2 | N86: 0.367 | O86: 1.3 | P86: 3.3 | Q86: 0.391 | R86: 0.47 | S86: 0.7 | T86: 0.8 | U86: 0.787 | V86: 0.3 | W86: 2.2 | X86: 2.4 | Y86: 2 | Z86: 0.5 | AA86: 0.2 | AB86: 0.9 | AC86: 1 | AD86: 6.8 | AE86: 993 | AF86: 10 | AG86: 0.493 | AH86: 0.495 | AI86: 0.129 | AJ86: 1.7 | AK86: 13.5 | AL86: 7.7 | AM86: 15.4 | AN86: 1.4 | AO86: 1.1 | AP86: 11.1 | AQ86: 18.9 | AR86: -0.4 | AS86: 0.8 | AT86: 0.4 | AU86: 0.021 | AV86: -2 | AW86: -0.6 | AX86: -2.6 | AY86: -0.2 | AZ86: =0.5*AX86 + 0.5*AT86 -> -1.1 | BA86: =IF(B86>0, AZ86*1000000/B86, 0) -> -0.073042565
A87: Tyus Jones | B87: 15000000 | C87: PG | D87: 26 | E87: MEM | F87: 80 | G87: 22 | H87: 24.3 | I87: 3.9 | J87: 8.9 | K87: 0.438 | L87: 1.5 | M87: 4.1 | N87: 0.371 | O87: 2.4 | P87: 4.8 | Q87: 0.495 | R87: 0.523 | S87: 1 | T87: 1.3 | U87: 0.8 | V87: 0.4 | W87: 2.2 | X87: 2.5 | Y87: 5.2 | Z87: 1 | AA87: 0.1 | AB87: 0.9 | AC87: 0.4 | AD87: 10.3 | AE87: 1940 | AF87: 16 | AG87: 0.546 | AH87: 0.459 | AI87: 0.141 | AJ87: 1.5 | AK87: 9.4 | AL87: 5.5 | AM87: 28.8 | AN87: 2 | AO87: 0.3 | AP87: 8.9 | AQ87: 17.7 | AR87: 3.4 | AS87: 2.3 | AT87: 5.7 | AU87: 0.141 | AV87: 1.2 | AW87: 0.3 | AX87: 1.6 | AY87: 1.7 | AZ87: =0.5*AX87 + 0.5*AT87 -> 3.65 | BA87: =IF(B87>0, AZ87*1000000/B87, 0) -> 0.24333333
A88: Derrick Rose | B88: 14520730 | C88: PG | D88: 34 | E88: NYK | F88: 27 | G88: 0 | H88: 12.5 | I88: 2.3 | J88: 5.9 | K88: 0.384 | L88: 0.7 | M88: 2.3 | N88: 0.302 | O88: 1.6 | P88: 3.6 | Q88: 0.438 | R88: 0.443 | S88: 0.4 | T88: 0.4 | U88: 0.917 | V88: 0.3 | W88: 1.2 | X88: 1.5 | Y88: 1.7 | Z88: 0.3 | AA88: 0.2 | AB88: 0.8 | AC88: 0.7 | AD88: 5.6 | AE88: 338 | AF88: 10.1 | AG88: 0.463 | AH88: 0.396 | AI88: 0.075 | AJ88: 2.6 | AK88: 10.4 | AL88: 6.5 | AM88: 19.9 | AN88: 1 | AO88: 1.4 | AP88: 11.8 | AQ88: 23.6 | AR88: -0.3 | AS88: 0.3 | AT88: 0 | AU88: -0.001 | AV88: -2.2 | AW88: -1.5 | AX88: -3.7 | AY88: -0.1 | AZ88: =0.5*AX88 + 0.5*AT88 -> -1.85 | BA88: =IF(B88>0, AZ88*1000000/B88, 0) -> -0.12740406
A89: Kevin Huerter | B89: 14508929 | C89: SG | D89: 24 | E89: SAC | F89: 75 | G89: 75 | H89: 29.4 | I89: 5.6 | J89: 11.5 | K89: 0.485 | L89: 2.7 | M89: 6.8 | N89: 0.402 | O89: 2.9 | P89: 4.7 | Q89: 0.604 | R89: 0.603 | S89: 1.3 | T89: 1.7 | U89: 0.725 | V89: 0.6 | W89: 2.8 | X89: 3.3 | Y89: 2.9 | Z89: 1.1 | AA89: 0.3 | AB89: 1.3 | AC89: 2.4 | AD89: 15.2 | AE89: 2203 | AF89: 15.2 | AG89: 0.617 | AH89: 0.589 | AI89: 0.151 | AJ89: 2.2 | AK89: 10.8 | AL89: 6.5 | AM89: 14.1 | AN89: 1.7 | AO89: 1 | AP89: 9.5 | AQ89: 19.9 | AR89: 3.3 | AS89: 1.7 | AT89: 4.9 | AU89: 0.107 | AV89: 1.4 | AW89: -0.3 | AX89: 1 | AY89: 1.7 | AZ89: =0.5*AX89 + 0.5*AT89 -> 2.95 | BA89: =IF(B89>0, AZ89*1000000/B89, 0) -> 0.20332307
... A134: Monte Morris | B134: 9125000 | C134: PG | D134: 27 | E134: WAS | F134: 62 | G134: 61 | H134: 27.3 | I134: 4 | J134: 8.3 | K134: 0.48 | L134: 1.3 | M134: 3.3 | N134: 0.382 | O134: 2.7 | P134: 5 | Q134: 0.543 | R134: 0.555 | S134: 1 | T134: 1.2 | U134: 0.831 | V134: 0.4 | W134: 3 | X134: 3.4 | Y134: 5.3 | Z134: 0.7 | AA134: 0.2 | AB134: 1 | AC134: 1.2 | AD134: 10.3 | AE134: 1695 | AF134: 15 | AG134: 0.579 | AH134: 0.396 | AI134: 0.15 | AJ134: 1.8 | AK134: 11.6 | AL134: 6.9 | AM134: 26.4 | AN134: 1.2 | AO134: 0.6 | AP134: 9.9 | AQ134: 15.6 | AR134: 3.1 | AS134: 1.1 | AT134: 4.2 | AU134: 0.12 | AV134: 0.8 | AW134: -0.4 | AX134: 0.5 | AY134: 1.1 | AZ134: =0.5*AX134 + 0.5*AT134 -> 2.35 | BA134: =IF(B134>0, AZ134*1000000/B134, 0) -> 0.25753425
A135: Mason Plumlee | B135: 9080417 | C135: C | D135: 32 | E135: CHA | F135: 79 | G135: 60 | H135: 26 | I135: 4.2 | J135: 6.1 | K135: 0.68 | L135: 0 | M135: 0 | O135: 4.2 | P135: 6.1 | Q135: 0.68 | R135: 0.68 | S135: 2.5 | T135: 4 | U135: 0.636 | V135: 2.9 | W135: 6 | X135: 8.9 | Y135: 3.1 | Z135: 0.6 | AA135: 0.6 | AB135: 1.5 | AC135: 2.7 | AD135: 10.8 | AE135: 2054 | AF135: 19.6 | AG135: 0.689 | AH135: 0 | AI135: 0.647 | AJ135: 11.8 | AK135: 25.1 | AL135: 18.4 | AM135: 17.3 | AN135: 1.1 | AO135: 2 | AP135: 15.8 | AQ135: 15.2 | AR135: 5.5 | AS135: 2.4 | AT135: 7.9 | AU135: 0.185 | AV135: 1.2 | AW135: 1 | AX135: 2.2 | AY135: 2.2 | AZ135: =0.5*AX135 + 0.5*AT135 -> 5.05 | BA135: =IF(B135>0, AZ135*1000000/B135, 0) -> 0.55614186
A136: Alex Caruso | B136: 9030000 | C136: PG | D136: 28 | E136: CHI | F136: 67 | G136: 36 | H136: 23.5 | I136: 1.9 | J136: 4.3 | K136: 0.455 | L136: 0.8 | M136: 2.3 | N136: 0.364 | O136: 1.1 | P136: 2 | Q136: 0.556 | R136: 0.551 | S136: 0.9 | T136: 1.1 | U136: 0.808 | V136: 0.6 | W136: 2.3 | X136: 2.9 | Y136: 2.9 | Z136: 1.5 | AA136: 0.7 | AB136: 1.1 | AC136: 2.4 | AD136: 5.6 | AE136: 1575 | AF136: 11.5 | AG136: 0.588 | AH136: 0.528 | AI136: 0.255 | AJ136: 3.1 | AK136: 10.9 | AL136: 7.1 | AM136: 15.4 | AN136: 3 | AO136: 2.8 | AP136: 19.5 | AQ136: 11.1 | AR136: 1 | AS136: 2.6 | AT136: 3.6 | AU136: 0.109 | AV136: -2.2 | AW136: 3.3 | AX136: 1.1 | AY136: 1.2 | AZ136: =0.5*AX136 + 0.5*AT136 -> 2.35 | BA136: =IF(B136>0, AZ136*1000000/B136, 0) -> 0.26024363
A137: Maxi Kleber | B137: 9000000 | C137: PF | D137: 31 | E137: DAL | F137: 37 | G137: 5 | H137: 25.1 | I137: 2.1 | J137: 4.6 | K137: 0.456 | L137: 1.1 | M137: 3 | N137: 0.348 | O137: 1 | P137: 1.5 | Q137: 0.667 | R137: 0.571 | S137: 0.7 | T137: 1 | U137: 0.711 | V137: 0.8 | W137: 2.8 | X137: 3.6 | Y137: 1.4 | Z137: 0.3 | AA137: 0.8 | AB137: 0.7 | AC137: 2.3 | AD137: 5.9 | AE137: 930 | AF137: 8.7 | AG137: 0.592 | AH137: 0.663 | AI137: 0.225 | AJ137: 3.7 | AK137: 13.3 | AL137: 8.4 | AM137: 7.5 | AN137: 0.6 | AO137: 2.9 | AP137: 12.7 | AQ137: 10.3 | AR137: 0.7 | AS137: 0.6 | AT137: 1.3 | AU137: 0.067 | AV137: -2.2 | AW137: 0 | AX137: -2.2 | AY137: 0 | AZ137: =0.5*AX137 + 0.5*AT137 -> -0.45 | BA137: =IF(B137>0, AZ137*1000000/B137, 0) -> -0.05
A138: Grayson Allen | B138: 8925000 | C138: SG | D138: 27 | E138: MIL | F138: 72 | G138: 70 | H138: 27.4 | I138: 3.4 | J138: 7.7 | K138: 0.44 | L138: 2 | M138: 5.1 | N138: 0.399 | O138: 1.4 | P138: 2.7 | Q138: 0.518 | R138: 0.571 | S138: 1.6 | T138: 1.8 | U138: 0.905 | V138: 0.8 | W138: 2.4 | X138: 3.3 | Y138: 2.3 | Z138: 0.9 | AA138: 0.2 | AB138: 1 | AC138: 1.6 | AD138: 10.4 | AE138: 1972 | AF138: 12.3 | AG138: 0.612 | AH138: 0.657 | AI138: 0.226 | AJ138: 3.4 | AK138: 9 | AL138: 6.3 | AM138: 10.9 | AN138: 1.5 | AO138: 0.6 | AP138: 10.5 | AQ138: 14.6 | AR138: 2.8 | AS138: 2.2 | AT138: 5.1 | AU138: 0.123 | AV138: -0.6 | AW138: 0.7 | AX138: 0.1 | AY138: 1 | AZ138: =0.5*AX138 + 0.5*AT138 -> 2.6 | BA138: =IF(B138>0, AZ138*1000000/B138, 0) -> 0.29131653
A139: Darius Garland | B139: 8920794 | C139: PG | D139: 23 | E139: CLE | F139: 69 | G139: 69 | H139: 35.5 | I139: 7.6 | J139: 16.4 | K139: 0.462 | L139: 2.4 | M139: 6 | N139: 0.41 | O139: 5.1 | P139: 10.4 | Q139: 0.492 | R139: 0.537 | S139: 4 | T139: 4.7 | U139: 0.863 | V139: 0.4 | W139: 2.3 | X139: 2.7 | Y139: 7.8 | Z139: 1.2 | AA139: 0.1 | AB139: 2.9 | AC139: 2.1 | AD139: 21.6 | AE139: 2447 | AF139: 18.8 | AG139: 0.587 | AH139: 0.365 | AI139: 0.284 | AJ139: 1.3 | AK139: 7.6 | AL139: 4.5 | AM139: 34.1 | AN139: 1.7 | AO139: 0.3 | AP139: 13.5 | AQ139: 26.9 | AR139: 4.5 | AS139: 3 | AT139: 7.6 | AU139: 0.148 | AV139: 3.2 | AW139: -0.7 | AX139: 2.4 | AY139: 2.7 | AZ139: =0.5*AX139 + 0.5*AT139 -> 5 | BA139: =IF(B139>0, AZ139*1000000/B139, 0) -> 0.56048823
A140: Isaiah Hartenstein | B140: 8854879 | C140: C | D140: 24 | E140: NYK | F140: 82 | G140: 8 | H140: 19.8 | I140: 2.1 | J140: 4 | K140: 0.535 | L140: 0.1 | M140: 0.5 | N140: 0.216 | O140: 2 | P140: 3.5 | Q140: 0.576 | R140: 0.547 | S140: 0.6 | T140: 0.9 | U140: 0.676 | V140: 2.5 | W140: 4 | X140: 6.5 | Y140: 1.2 | Z140: 0.6 | AA140: 0.8 | AB140: 0.8 | AC140: 2.6 | AD140: 5 | AE140: 1626 | AF140: 14.2 | AG140: 0.567 | AH140: 0.113 | AI140: 0.217 | AJ140: 14.1 | AK140: 22.2 | AL140: 18.1 | AM140: 8.3 | AN140: 1.6 | AO140: 3.7 | AP140: 15.6 | AQ140: 11.2 | AR140: 2.2 | AS140: 2.4 | AT140: 4.6 | AU140: 0.136 | AV140: -1.5 | AW140: 1.2 | AX140: -0.3 | AY140: 0.7 | AZ140: =0.5*AX140 + 0.5*AT140 -> 2.15 | BA140: =IF(B140>0, AZ140*1000000/B140, 0) -> 0.242804
A141: Kyle Anderson | B141: 8780488 | C141: PF | D141: 29 | E141: MIN | F141: 69 | G141: 46 | H141: 28.4 | I141: 3.7 | J141: 7.2 | K141: 0.509 | L141: 0.6 | M141: 1.5 | N141: 0.41 | O141: 3 | P141: 5.7 | Q141: 0.536 | R141: 0.553 | S141: 1.4 | T141: 2 | U141: 0.735 | V141: 1 | W141: 4.4 | X141: 5.3 | Y141: 4.9 | Z141: 1.1 | AA141: 0.9 | AB141: 1.5 | AC141: 2.1 | AD141: 9.4 | AE141: 1957 | AF141: 14.8 | AG141: 0.583 | AH141: 0.212 | AI141: 0.275 | AJ141: 3.8 | AK141: 16.9 | AL141: 10.5 | AM141: 22.6 | AN141: 1.9 | AO141: 2.8 | AP141: 15.7 | AQ141: 14.4 | AR141: 2.5 | AS141: 2.6 | AT141: 5.1 | AU141: 0.125 | AV141: 0.2 | AW141: 2.3 | AX141: 2.5 | AY141: 2.2 | AZ141: =0.5*AX141 + 0.5*AT141 -> 3.8 | BA141: =IF(B141>0, AZ141*1000000/B141, 0) -> 0.43277777
A142: Victor Oladipo | B142: 8750000 | C142: SG | D142: 30 | E142: MIA | F142: 42 | G142: 2 | H142: 26.3 | I142: 3.8 | J142: 9.6 | K142: 0.397 | L142: 1.7 | M142: 5 | N142: 0.33 | O142: 2.1 | P142: 4.5 | Q142: 0.471 | R142: 0.484 | S142: 1.4 | T142: 1.9 | U142: 0.747 | V142: 0.4 | W142: 2.7 | X142: 3 | Y142: 3.5 | Z142: 1.4 | AA142: 0.3 | AB142: 2.1 | AC142: 2.4 | AD142: 10.7 | AE142: 1106 | AF142: 10.6 | AG142: 0.513 | AH142: 0.526 | AI142: 0.196 | AJ142: 1.6 | AK142: 12.3 | AL142: 6.8 | AM142: 19.8 | AN142: 2.6 | AO142: 1.1 | AP142: 16.6 | AQ142: 21.1 | AR142: -0.9 | AS142: 1.5 | AT142: 0.6 | AU142: 0.024 | AV142: -2.9 | AW142: 0.8 | AX142: -2.1 | AY142: 0 | AZ142: =0.5*AX142 + 0.5*AT142 -> -0.75 | BA142: =IF(B142>0, AZ142*1000000/B142, 0) -> -0.085714286
A143: Daniel Theis | B143: 8694369 | C143: C | D143: 30 | E143: IND | F143: 7 | G143: 1 | H143: 15.6 | I143: 3 | J143: 6.3 | K143: 0.477 | L143: 0.3 | M143: 1.6 | N143: 0.182 | O143: 2.7 | P143: 4.7 | Q143: 0.576 | R143: 0.5 | S143: 0.7 | T143: 1.7 | U143: 0.417 | V143: 1 | W143: 2.1 | X143: 3.1 | Y143: 1.3 | Z143: 0.3 | AA143: 0.9 | AB143: 0.4 | AC143: 1 | AD143: 7 | AE143: 109 | AF143: 14.2 | AG143: 0.497 | AH143: 0.25 | AI143: 0.273 | AJ143: 7.1 | AK143: 15.2 | AL143: 11.2 | AM143: 12.2 | AN143: 0.9 | AO143: 4.7 | AP143: 5.7 | AQ143: 20.1 | AR143: 0 | AS143: 0.1 | AT143: 0.1 | AU143: 0.046 | AV143: -0.9 | AW143: -0.5 | AX143: -1.4 | AY143: 0 | AZ143: =0.5*AX143 + 0.5*AT143 -> -0.65 | BA143: =IF(B143>0, AZ143*1000000/B143, 0) -> -0.074761032
A144: LaMelo Ball | B144: 8623920 | C144: PG | D144: 21 | E144: CHA | F144: 36 | G144: 36 | H144: 35.2 | I144: 8.2 | J144: 20 | K144: 0.411 | L144: 4 | M144: 10.6 | N144: 0.376 | O144: 4.2 | P144: 9.4 | Q144: 0.45 | R144: 0.51 | S144: 2.8 | T144: 3.4 | U144: 0.836 | V144: 1.2 | W144: 5.3 | X144: 6.4 | Y144: 8.4 | Z144: 1.3 | AA144: 0.3 | AB144: 3.6 | AC144: 3.3 | AD144: 23.3 | AE144: 1268 | AF144: 17.9 | AG144: 0.541 | AH144: 0.531 | AI144: 0.169 | AJ144: 3.5 | AK144: 16.2 | AL144: 9.7 | AM144: 38.7 | AN144: 1.7 | AO144: 0.8 | AP144: 14.3 | AQ144: 30 | AR144: 0.6 | AS144: 1.2 | AT144: 1.8 | AU144: 0.068 | AV144: 3.2 | AW144: -0.8 | AX144: 2.4 | AY144: 1.4 | AZ144: =0.5*AX144 + 0.5*AT144 -> 2.1 | BA144: =IF(B144>0, AZ144*1000000/B144, 0) -> 0.24350875
A145: Seth Curry | B145: 8496653 | C145: SG | D145: 32 | E145: BKN | F145: 61 | G145: 7 | H145: 19.9 | I145: 3.4 | J145: 7.4 | K145: 0.463 | L145: 1.5 | M145: 3.8 | N145: 0.405 | O145: 1.9 | P145: 3.6 | Q145: 0.525 | R145: 0.568 | S145: 0.8 | T145: 0.9 | U145: 0.927 | V145: 0.2 | W145: 1.4 | X145: 1.6 | Y145: 1.6 | Z145: 0.6 | AA145: 0.1 | AB145: 0.8 | AC145: 1.6 | AD145: 9.2 | AE145: 1211 | AF145: 12.3 | AG145: 0.593 | AH145: 0.517 | AI145: 0.122 | AJ145: 1.2 | AK145: 7.9 | AL145: 4.6 | AM145: 11.9 | AN145: 1.5 | AO145: 0.5 | AP145: 9.7 | AQ145: 19.2 | AR145: 0.9 | AS145: 0.9 | AT145: 1.8 | AU145: 0.07 | AV145: -1.2 | AW145: -0.9 | AX145: -2.1 | AY145: 0 | AZ145: =0.5*AX145 + 0.5*AT145 -> -0.15 | BA145: =IF(B145>0, AZ145*1000000/B145, 0) -> -0.01765401
A146: Evan Mobley | B146: 8478720 | C146: PF | D146: 21 | E146: CLE | F146: 79 | G146: 79 | H146: 34.4 | I146: 6.6 | J146: 12 | K146: 0.554 | L146: 0.3 | M146: 1.3 | N146: 0.216 | O146: 6.4 | P146: 10.7 | Q146: 0.595 | R146: 0.566 | S146: 2.6 | T146: 3.8 | U146: 0.674 | V146: 2.4 | W146: 6.6 | X146: 9 | Y146: 2.8 | Z146: 0.8 | AA146: 1.5 | AB146: 1.8 | AC146: 2.8 | AD146: 16.2 | AE146: 2715 | AF146: 17.9 | AG146: 0.591 | AH146: 0.108 | AI146: 0.321 | AJ146: 8.1 | AK146: 22.7 | AL146: 15.4 | AM146: 12.4 | AN146: 1.1 | AO146: 4 | AP146: 11.9 | AQ146: 20.2 | AR146: 3.7 | AS146: 4.8 | AT146: 8.5 | AU146: 0.151 | AV146: 0 | AW146: 1.6 | AX146: 1.7 | AY146: 2.5 | AZ146: =0.5*AX146 + 0.5*AT146 -> 5.1 | BA146: =IF(B146>0, AZ146*1000000/B146, 0) -> 0.60150589
...

Sheet LP_RosterModel
A1: Player Name | B1: Salary | C1: Position | D1: Age | E1: Team | F1: GP | G1: GS | H1: MP | I1: FG | J1: FGA | K1: FG% | L1: 3P | M1: 3PA | N1: 3P% | O1: 2P | P1: 2PA | Q1: 2P% | R1: eFG% | S1: FT | T1: FTA | U1: FT% | V1: ORB | W1: DRB | X1: TRB | Y1: AST | Z1: STL | AA1: BLK | AB1: TOV | AC1: PF | AD1: PTS | AE1: Total Minutes | AF1: PER | AG1: TS% | AH1: 3PAr | AI1: FTr | AJ1: ORB% | AK1: DRB% | AL1: TRB% | AM1: AST% | AN1: STL% | AO1: BLK% | AP1: TOV% | AQ1: USG% | AR1: OWS | AS1: DWS | AT1: WS | AU1: WS/48 | AV1: OBPM | AW1: DBPM | AX1: BPM | AY1: VORP | AZ1: Score | BA1: Score_per_$M | BB1: Decision Variable | BD1: Total Score | BE1: Total Salary | BF1: Total Players | BG1: PG_Count | BH1: SG_Count | BI1: SF_Count | BJ1: PF_Count | BK1: C_Count | BL1: Cap | BM1: Roster Size
A2: Domantas Sabonis | B2: 21100000 | C2: C | D2: 26 | E2: SAC | F2: 79 | G2: 79 | H2: 34.6 | I2: 7.3 | J2: 11.9 | K2: 0.615 | L2: 0.4 | M2: 1.1 | N2: 0.373 | O2: 6.9 | P2: 10.8 | Q2: 0.639 | R2: 0.632 | S2: 4.1 | T2: 5.5 | U2: 0.742 | V2: 3.2 | W2: 9.1 | X2: 12.3 | Y2: 7.3 | Z2: 0.8 | AA2: 0.5 | AB2: 2.9 | AC2: 3.5 | AD2: 19.1 | AE2: 2736 | AF2: 23.5 | AG2: 0.668 | AH2: 0.088 | AI2: 0.467 | AJ2: 10.6 | AK2: 30 | AL2: 20.3 | AM2: 30.4 | AN2: 1.1 | AO2: 1.2 | AP2: 16.9 | AQ2: 21.3 | AR2: 9.6 | AS2: 3 | AT2: 12.6 | AU2: 0.221 | AV2: 4.1 | AW2: 1.8 | AX2: 5.8 | AY2: 5.4 | AZ2: 9.2 | BA2: 0.43601896 | BB2: 1 | BD2: =SUMPRODUCT(AZ2:AZ193, BB2:BB193) -> 68.997044 | BE2: =SUMPRODUCT(B2:B193, BB2:BB193) -> 1.54e+08 | BF2: =SUM(BB2:BB193) -> 12 | BG2: {=SUMPRODUCT(BB2:BB193, --(C2:C193="PG"))} -> 2 | BH2: {=SUMPRODUCT(BB2:BB193, --(C2:C193="SG"))} -> 3 | BI2: {=SUMPRODUCT(BB2:BB193, --(C2:C193="SF"))} -> 2 | BJ2: {=SUMPRODUCT(BB2:BB193, --(C2:C193="PF"))} -> 2 | BK2: {=SUMPRODUCT(BB2:BB193, --(C2:C193="C"))} -> 3 | BL2: 154000000 | BM2: 12
A3: Evan Mobley | B3: 8478720 | C3: PF | D3: 21 | E3: CLE | F3: 79 | G3: 79 | H3: 34.4 | I3: 6.6 | J3: 12 | K3: 0.554 | L3: 0.3 | M3: 1.3 | N3: 0.216 | O3: 6.4 | P3: 10.7 | Q3: 0.595 | R3: 0.566 | S3: 2.6 | T3: 3.8 | U3: 0.674 | V3: 2.4 | W3: 6.6 | X3: 9 | Y3: 2.8 | Z3: 0.8 | AA3: 1.5 | AB3: 1.8 | AC3: 2.8 | AD3: 16.2 | AE3: 2715 | AF3: 17.9 | AG3: 0.591 | AH3: 0.108 | AI3: 0.321 | AJ3: 8.1 | AK3: 22.7 | AL3: 15.4 | AM3: 12.4 | AN3: 1.1 | AO3: 4 | AP3: 11.9 | AQ3: 20.2 | AR3: 3.7 | AS3: 4.8 | AT3: 8.5 | AU3: 0.151 | AV3: 0 | AW3: 1.6 | AX3: 1.7 | AY3: 2.5 | AZ3: 5.1 | BA3: 0.60150589 | BB3: 1 | BL3: BB193 | BM3: = | BN3: 1 | BO3: Luka
A4: Kevon Looney | B4: 8000000 | C4: C | D4: 26 | E4: GSW | F4: 82 | G4: 70 | H4: 23.9 | I4: 3 | J4: 4.7 | K4: 0.63 | L4: 0 | M4: 0 | N4: 0 | O4: 3 | P4: 4.7 | Q4: 0.632 | R4: 0.63 | S4: 1.1 | T4: 1.9 | U4: 0.606 | V4: 3.3 | W4: 5.9 | X4: 9.3 | Y4: 2.5 | Z4: 0.6 | AA4: 0.6 | AB4: 0.5 | AC4: 2.7 | AD4: 7 | AE4: 1958 | AF4: 17.8 | AG4: 0.639 | AH4: 0.003 | AI4: 0.404 | AJ4: 15.7 | AK4: 26.8 | AL4: 21.4 | AM4: 13.8 | AN4: 1.3 | AO4: 2.2 | AP4: 9.1 | AQ4: 10.6 | AR4: 5.9 | AS4: 2.8 | AT4: 8.7 | AU4: 0.212 | AV4: 0.9 | AW4: 1.3 | AX4: 2.1 | AY4: 2 | AZ4: 5.4 | BA4: 0.675 | BB4: 1 | BL4: BB28 | BM4: = | BN4: 1 | BO4: Kyrie
A5: Tyrese Haliburton | B5: 4215120 | C5: PG | D5: 22 | E5: IND | F5: 56 | G5: 56 | H5: 33.6 | I5: 7.4 | J5: 15 | K5: 0.49 | L5: 2.9 | M5: 7.2 | N5: 0.4 | O5: 4.5 | P5: 7.8 | Q5: 0.572 | R5: 0.586 | S5: 3.1 | T5: 3.6 | U5: 0.871 | V5: 0.6 | W5: 3.1 | X5: 3.7 | Y5: 10.4 | Z5: 1.6 | AA5: 0.4 | AB5: 2.5 | AC5: 1.2 | AD5: 20.7 | AE5: 1883 | AF5: 23.6 | AG5: 0.624 | AH5: 0.478 | AI5: 0.239 | AJ5: 1.9 | AK5: 10.1 | AL5: 6 | AM5: 47.6 | AN5: 2.3 | AO5: 1.1 | AP5: 13.2 | AQ5: 23.8 | AR5: 6.4 | AS5: 1.2 | AT5: 7.6 | AU5: 0.195 | AV5: 7 | AW5: 0.2 | AX5: 7.2 | AY5: 4.4 | AZ5: 7.4 | BA5: 1.7555847 | BB5: 1
A6: Walker Kessler | B6: 2696400 | C6: C | D6: 21 | E6: UTA | F6: 74 | G6: 40 | H6: 23 | I6: 4 | J6: 5.6 | K6: 0.72 | L6: 0 | M6: 0 | N6: 0.333 | O6: 4 | P6: 5.6 | Q6: 0.723 | R6: 0.721 | S6: 1.1 | T6: 2.1 | U6: 0.516 | V6: 3.1 | W6: 5.3 | X6: 8.4 | Y6: 0.9 | Z6: 0.4 | AA6: 2.3 | AB6: 0.8 | AC6: 2.3 | AD6: 9.2 | AE6: 1703 | AF6: 21.5 | AG6: 0.702 | AH6: 0.007 | AI6: 0.384 | AJ6: 14.9 | AK6: 24.4 | AL6: 19.7 | AM6: 5.7 | AN6: 0.7 | AO6: 8.6 | AP6: 10.7 | AQ6: 13.3 | AR6: 4.6 | AS6: 2.5 | AT6: 7.1 | AU6: 0.2 | AV6: 1.4 | AW6: 1.5 | AX6: 2.9 | AY6: 2.1 | AZ6: 5 | BA6: 1.8543243 | BB6: 1
A7: Immanuel Quickley | B7: 2316240 | C7: SG | D7: 23 | E7: NYK | F7: 81 | G7: 21 | H7: 28.9 | I7: 5.2 | J7: 11.6 | K7: 0.448 | L7: 2.1 | M7: 5.6 | N7: 0.37 | O7: 3.1 | P7: 6 | Q7: 0.521 | R7: 0.537 | S7: 2.5 | T7: 3.1 | U7: 0.819 | V7: 0.7 | W7: 3.4 | X7: 4.2 | Y7: 3.4 | Z7: 1 | AA7: 0.2 | AB7: 1.2 | AC7: 2 | AD7: 14.9 | AE7: 2344 | AF7: 16.3 | AG7: 0.578 | AH7: 0.485 | AI7: 0.265 | AJ7: 2.7 | AK7: 13.1 | AL7: 7.9 | AM7: 17.4 | AN7: 1.7 | AO7: 0.6 | AP7: 8.7 | AQ7: 20.9 | AR7: 4.4 | AS7: 2.3 | AT7: 6.7 | AU7: 0.137 | AV7: 1.3 | AW7: 0.4 | AX7: 1.7 | AY7: 2.1 | AZ7: 4.2 | BA7: 1.8132836 | BB7: 1
A8: Desmond Bane | B8: 2130240 | C8: SG | D8: 24 | E8: MEM | F8: 58 | G8: 58 | H8: 31.7 | I8: 7.8 | J8: 16.2 | K8: 0.479 | L8: 2.9 | M8: 7 | N8: 0.408 | O8: 4.9 | P8: 9.2 | Q8: 0.534 | R8: 0.568 | S8: 3.1 | T8: 3.5 | U8: 0.883 | V8: 0.7 | W8: 4.3 | X8: 5 | Y8: 4.4 | Z8: 1 | AA8: 0.4 | AB8: 2.2 | AC8: 2.6 | AD8: 21.5 | AE8: 1841 | AF8: 19.1 | AG8: 0.606 | AH8: 0.433 | AI8: 0.218 | AJ8: 2.5 | AK8: 14.3 | AL8: 8.4 | AM8: 20.8 | AN8: 1.4 | AO8: 1.1 | AP8: 10.9 | AQ8: 26.1 | AR8: 3.5 | AS8: 2.3 | AT8: 5.8 | AU8: 0.151 | AV8: 3.3 | AW8: 0.1 | AX8: 3.5 | AY8: 2.5 | AZ8: 4.65 | BA8: 2.1828526 | BB8: 1
A9: Sam Hauser | B9: 1637966 | C9: SF | D9: 25 | E9: BOS | F9: 80 | G9: 8 | H9: 16.1 | I9: 2.3 | J9: 5 | K9: 0.455 | L9: 1.8 | M9: 4.2 | N9: 0.418 | O9: 0.5 | P9: 0.8 | Q9: 0.656 | R9: 0.631 | S9: 0.2 | T9: 0.2 | U9: 0.706 | V9: 0.4 | W9: 2.1 | X9: 2.6 | Y9: 0.9 | Z9: 0.4 | AA9: 0.3 | AB9: 0.4 | AC9: 1.2 | AD9: 6.4 | AE9: 1290 | AF9: 12.7 | AG9: 0.634 | AH9: 0.846 | AI9: 0.043 | AJ9: 3 | AK9: 14.1 | AL9: 8.6 | AM9: 7.6 | AN9: 1.1 | AO9: 1.4 | AP9: 6.9 | AQ9: 14.7 | AR9: 1.8 | AS9: 1.6 | AT9: 3.4 | AU9: 0.128 | AV9: 0.6 | AW9: 0.4 | AX9: 1 | AY9: 1 | AZ9: 2.2 | BA9: 1.3431292 | BB9: 1
A10: Brandon Clarke | B10: 4343919 | C10: PF | D10: 26 | E10: MEM | F10: 56 | G10: 8 | H10: 19.5 | I10: 4.1 | J10: 6.2 | K10: 0.656 | L10: 0 | M10: 0.1 | N10: 0.167 | O10: 4.1 | P10: 6.1 | Q10: 0.665 | R10: 0.658 | S10: 1.8 | T10: 2.4 | U10: 0.723 | V10: 1.6 | W10: 3.9 | X10: 5.5 | Y10: 1.3 | Z10: 0.6 | AA10: 0.7 | AB10: 1 | AC10: 2.3 | AD10: 10 | AE10: 1090 | AF10: 20 | AG10: 0.682 | AH10: 0.017 | AI10: 0.393 | AJ10: 9 | AK10: 21.2 | AL10: 15.1 | AM10: 9.5 | AN10: 1.5 | AO10: 3.1 | AP10: 11.8 | AQ10: 17.7 | AR10: 2.7 | AS10: 1.8 | AT10: 4.5 | AU10: 0.199 | AV10: 0.8 | AW10: 1.8 | AX10: 2.5 | AY10: 1.3 | AZ10: 3.5 | BA10: 0.80572405 | BB10: 1
A11: Kyrie Irving | B11: 38917057 | C11: SG | D11: 30 | E11: DAL | F11: 60 | G11: 60 | H11: 37.4 | I11: 9.9 | J11: 20.1 | K11: 0.494 | L11: 3.1 | M11: 8.3 | N11: 0.379 | O11: 6.8 | P11: 11.8 | Q11: 0.574 | R11: 0.572 | S11: 4.1 | T11: 4.6 | U11: 0.905 | V11: 1 | W11: 4.1 | X11: 5.1 | Y11: 5.5 | Z11: 1.1 | AA11: 0.8 | AB11: 2.1 | AC11: 2.8 | AD11: 27.1 | AE11: 2241 | AF11: 22.4 | AG11: 0.613 | AH11: 0.412 | AI11: 0.227 | AJ11: 3 | AK11: 12.3 | AL11: 7.7 | AM11: 25.4 | AN11: 1.4 | AO11: 1.7 | AP11: 8.8 | AQ11: 28.9 | AR11: 5.4 | AS11: 2 | AT11: 7.4 | AU11: 0.159 | AV11: 4.8 | AW11: -0.7 | AX11: 4.1 | AY11: 3.5 | AZ11: 5.75 | BA11: 0.14775012 | BB11: 1
A12: Luka Doncic | B12: 37096500 | C12: PG | AT12: 12.1 | AX12: 8.2 | AZ12: 10.15 | BA12: 0.27361072 | BB12: 1
A13: Jayson Tatum | B13: 30351780 | C13: SF | D13: 24 | E13: BOS | F13: 74 | G13: 74 | H13: 36.9 | I13: 9.8 | J13: 21.1 | K13: 0.466 | L13: 3.2 | M13: 9.3 | N13: 0.35 | O13: 6.6 | P13: 11.8 | Q13: 0.558 | R13: 0.543 | S13: 7.2 | T13: 8.4 | U13: 0.854 | V13: 1.1 | W13: 7.7 | X13: 8.8 | Y13: 4.6 | Z13: 1.1 | AA13: 0.7 | AB13: 2.9 | AC13: 2.2 | AD13: 30.1 | AE13: 2732 | AF13: 23.7 | AG13: 0.607 | AH13: 0.44 | AI13: 0.399 | AJ13: 3.2 | AK13: 22.5 | AL13: 13 | AM13: 20.9 | AN13: 1.4 | AO13: 1.6 | AP13: 10.4 | AQ13: 32.7 | AR13: 6.2 | AS13: 4.3 | AT13: 10.5 | AU13: 0.185 | AV13: 4.8 | AW13: 0.7 | AX13: 5.5 | AY13: 5.1 | AZ13: 8 | BA13: 0.26357597 | BB13: 0.70972794
A14: Franz Wagner | B14: 5258280 | C14: SF | D14: 21 | E14: ORL | F14: 80 | G14: 80 | H14: 32.6 | I14: 6.8 | J14: 14 | K14: 0.485 | L14: 1.6 | M14: 4.5 | N14: 0.361 | O14: 5.2 | P14: 9.5 | Q14: 0.544 | R14: 0.543 | S14: 3.4 | T14: 4 | U14: 0.842 | V14: 0.9 | W14: 3.2 | X14: 4.1 | Y14: 3.5 | Z14: 1 | AA14: 0.2 | AB14: 2.1 | AC14: 2.3 | AD14: 18.6 | AE14: 2609 | AF14: 15.9 | AG14: 0.589 | AH14: 0.322 | AI14: 0.288 | AJ14: 3 | AK14: 11.2 | AL14: 7.1 | AM14: 17.2 | AN14: 1.4 | AO14: 0.6 | AP14: 11.7 | AQ14: 23.5 | AR14: 3.1 | AS14: 2.3 | AT14: 5.4 | AU14: 0.099 | AV14: 0.4 | AW14: -0.5 | AX14: -0.1 | AY14: 1.3 | AZ14: 2.65 | BA14: 0.50396708 | BB14: 0.29027206
A15: Joel Embiid | B15: 33616770 | C15: C | D15: 28 | E15: PHI | F15: 66 | G15: 66 | H15: 34.6 | I15: 11 | J15: 20.1 | K15: 0.548 | L15: 1 | M15: 3 | N15: 0.33 | O15: 10 | P15: 17.1 | Q15: 0.587 | R15: 0.573 | S15: 10 | T15: 11.7 | U15: 0.857 | V15: 1.7 | W15: 8.4 | X15: 10.2 | Y15: 4.2 | Z15: 1 | AA15: 1.7 | AB15: 3.4 | AC15: 3.1 | AD15: 33.1 | AE15: 2284 | AF15: 31.4 | AG15: 0.655 | AH15: 0.151 | AI15: 0.581 | AJ15: 5.9 | AK15: 28.3 | AL15: 17.3 | AM15: 22.9 | AN15: 1.4 | AO15: 4.6 | AP15: 11.9 | AQ15: 37 | AR15: 8.4 | AS15: 3.9 | AT15: 12.3 | AU15: 0.259 | AV15: 6.8 | AW15: 2.3 | AX15: 9.2 | AY15: 6.4 | AZ15: 10.75 | BA15: 0.31978087 | BB15: 2.220446e-16
A16: Ja Morant | B16: 12119440 | C16: PG | D16: 23 | E16: MEM | F16: 61 | G16: 59 | H16: 31.9 | I16: 9.3 | J16: 19.9 | K16: 0.466 | L16: 1.5 | M16: 4.9 | N16: 0.307 | O16: 7.8 | P16: 15 | Q16: 0.519 | R16: 0.504 | S16: 6.1 | T16: 8.1 | U16: 0.748 | V16: 1 | W16: 4.9 | X16: 5.9 | Y16: 8.1 | Z16: 1.1 | AA16: 0.3 | AB16: 3.4 | AC16: 1.6 | AD16: 26.2 | AE16: 1948 | AF16: 23.3 | AG16: 0.557 | AH16: 0.247 | AI16: 0.409 | AJ16: 3.3 | AK16: 16.1 | AL16: 9.7 | AM16: 41.1 | AN16: 1.6 | AO16: 0.7 | AP16: 12.6 | AQ16: 34.9 | AR16: 3.4 | AS16: 2.6 | AT16: 6 | AU16: 0.148 | AV16: 5.2 | AW16: 0.5 | AX16: 5.7 | AY16: 3.8 | AZ16: 5.85 | BA16: 0.48269557 | BB16: 0
A17: Jimmy Butler | B17: 37653300 | C17: PF | D17: 33 | E17: MIA | F17: 64 | G17: 64 | H17: 33.4 | I17: 7.5 | J17: 13.9 | K17: 0.539 | L17: 0.6 | M17: 1.6 | N17: 0.35 | O17: 6.9 | P17: 12.3 | Q17: 0.564 | R17: 0.56 | S17: 7.4 | T17: 8.7 | U17: 0.85 | V17: 2.2 | W17: 3.7 | X17: 5.9 | Y17: 5.3 | Z17: 1.8 | AA17: 0.3 | AB17: 1.6 | AC17: 1.3 | AD17: 22.9 | AE17: 2138 | AF17: 27.6 | AG17: 0.647 | AH17: 0.116 | AI17: 0.625 | AJ17: 7.5 | AK17: 13.3 | AL17: 10.3 | AM17: 27.1 | AN17: 2.7 | AO17: 1 | AP17: 8.2 | AQ17: 25.6 | AR17: 9.4 | AS17: 2.9 | AT17: 12.3 | AU17: 0.277 | AV17: 6.7 | AW17: 2 | AX17: 8.7 | AY17: 5.8 | AZ17: 10.5 | BA17: 0.27886002 | BB17: 0
A18: Austin Reaves | B18: 1563518 | C18: SG | D18: 24 | E18: LAL | F18: 64 | G18: 22 | H18: 28.8 | I18: 4 | J18: 7.7 | K18: 0.529 | L18: 1.3 | M18: 3.4 | N18: 0.398 | O18: 2.7 | P18: 4.3 | Q18: 0.631 | R18: 0.616 | S18: 3.6 | T18: 4.1 | U18: 0.864 | V18: 0.5 | W18: 2.5 | X18: 3 | Y18: 3.4 | Z18: 0.5 | AA18: 0.3 | AB18: 1.5 | AC18: 1.7 | AD18: 13 | AE18: 1843 | AF18: 14.9 | AG18: 0.687 | AH18: 0.441 | AI18: 0.541 | AJ18: 2 | AK18: 9 | AL18: 5.6 | AM18: 15.7 | AN18: 0.8 | AO18: 0.9 | AP18: 14 | AQ18: 16.2 | AR18: 4.1 | AS18: 1.4 | AT18: 5.4 | AU18: 0.142 | AV18: 0.6 | AW18: 0.1 | AX18: 0.7 | AY18: 1.2 | AZ18: 3.05 | BA18: 1.9507291 | BB18: 0
A19: Daniel Gafford | B19: 1930681 | C19: C | D19: 24 | E19: WAS | F19: 78 | G19: 47 | H19: 20.6 | I19: 3.7 | J19: 5.1 | K19: 0.732 | L19: 0 | M19: 0 | O19: 3.7 | P19: 5.1 | Q19: 0.732 | R19: 0.732 | S19: 1.6 | T19: 2.4 | U19: 0.679 | V19: 2.1 | W19: 3.5 | X19: 5.6 | Y19: 1.1 | Z19: 0.4 | AA19: 1.3 | AB19: 1.1 | AC19: 2.4 | AD19: 9 | AE19: 1604 | AF19: 19.7 | AG19: 0.739 | AH19: 0 | AI19: 0.473 | AJ19: 11.7 | AK19: 18 | AL19: 15 | AM19: 7.5 | AN19: 1 | AO19: 5.2 | AP19: 15.1 | AQ19: 15.2 | AR19: 4.2 | AS19: 1.9 | AT19: 6.1 | AU19: 0.184 | AV19: 0.4 | AW19: 0.6 | AX19: 1 | AY19: 1.2 | AZ19: 3.55 | BA19: 1.8387294 | BB19: 0
A20: Stephen Curry | B20: 48070014 | C20: PG | D20: 34 | E20: GSW | F20: 56 | G20: 56 | H20: 34.7 | I20: 10 | J20: 20.2 | K20: 0.493 | L20: 4.9 | M20: 11.4 | N20: 0.427 | O20: 5.1 | P20: 8.8 | Q20: 0.579 | R20: 0.614 | S20: 4.6 | T20: 5 | U20: 0.915 | V20: 0.7 | W20: 5.4 | X20: 6.1 | Y20: 6.3 | Z20: 0.9 | AA20: 0.4 | AB20: 3.2 | AC20: 2.1 | AD20: 29.4 | AE20: 1941 | AF20: 24.1 | AG20: 0.656 | AH20: 0.564 | AI20: 0.248 | AJ20: 2.3 | AK20: 16.8 | AL20: 9.7 | AM20: 30 | AN20: 1.3 | AO20: 0.9 | AP20: 12.5 | AQ20: 31 | AR20: 5.8 | AS20: 2 | AT20: 7.8 | AU20: 0.192 | AV20: 7.5 | AW20: 0.1 | AX20: 7.5 | AY20: 4.7 | AZ20: 7.65 | BA20: 0.15914287 | BB20: 0
A21: Russell Westbrook | B21: 47080179 | C21: PG | D21: 34 | E21: LAC | F21: 73 | G21: 24 | H21: 29.1 | I21: 5.9 | J21: 13.6 | K21: 0.436 | L21: 1.2 | M21: 3.9 | N21: 0.311 | O21: 4.7 | P21: 9.7 | Q21: 0.487 | R21: 0.481 | S21: 2.8 | T21: 4.3 | U21: 0.656 | V21: 1.2 | W21: 4.6 | X21: 5.8 | Y21: 7.5 | Z21: 1 | AA21: 0.5 | AB21: 3.5 | AC21: 2.2 | AD21: 15.9 | AE21: 2126 | AF21: 16.1 | AG21: 0.513 | AH21: 0.289 | AI21: 0.317 | AJ21: 4.7 | AK21: 16.5 | AL21: 10.8 | AM21: 38.6 | AN21: 1.7 | AO21: 1.3 | AP21: 18.4 | AQ21: 27.7 | AR21: -0.6 | AS21: 2.6 | AT21: 1.9 | AU21: 0.044 | AV21: 0.3 | AW21: -0.1 | AX21: 0.2 | AY21: 1.2 | AZ21: 1.05 | BA21: 0.022302379 | BB21: 0
A22: LeBron James | B22: 44474988 | C22: PF | D22: 38 | E22: LAL | F22: 55 | G22: 54 | H22: 35.5 | I22: 11.1 | J22: 22.2 | K22: 0.5 | L22: 2.2 | M22: 6.9 | N22: 0.321 | O22: 8.9 | P22: 15.3 | Q22: 0.58 | R22: 0.549 | S22: 4.6 | T22: 5.9 | U22: 0.768 | V22: 1.2 | W22: 7.1 | X22: 8.3 | Y22: 6.8 | Z22: 0.9 | AA22: 0.6 | AB22: 3.2 | AC22: 1.6 | AD22: 28.9 | AE22: 1954 | AF22: 23.9 | AG22: 0.583 | AH22: 0.309 | AI22: 0.268 | AJ22: 3.7 | AK22: 20.8 | AL22: 12.5 | AM22: 33.5 | AN22: 1.2 | AO22: 1.4 | AP22: 11.6 | AQ22: 33.3 | AR22: 3.2 | AS22: 2.4 | AT22: 5.6 | AU22: 0.138 | AV22: 5.5 | AW22: 0.6 | AX22: 6.1 | AY22: 4 | AZ22: 5.85 | BA22: 0.13153461 | BB22: 0
A23: Kevin Durant | B23: 44119845 | C23: PF | D23: 34 | E23: PHO | F23: 47 | G23: 47 | H23: 35.6 | I23: 10.3 | J23: 18.3 | K23: 0.56 | L23: 2 | M23: 4.9 | N23: 0.404 | O23: 8.3 | P23: 13.4 | Q23: 0.617 | R23: 0.614 | S23: 6.5 | T23: 7.1 | U23: 0.919 | V23: 0.4 | W23: 6.3 | X23: 6.7 | Y23: 5 | Z23: 0.7 | AA23: 1.4 | AB23: 3.3 | AC23: 2.1 | AD23: 29.1 | AE23: 1672 | AF23: 25.9 | AG23: 0.677 | AH23: 0.267 | AI23: 0.387 | AJ23: 1.2 | AK23: 19.5 | AL23: 10.5 | AM23: 24.5 | AN23: 1 | AO23: 3.4 | AP23: 13.4 | AQ23: 30.7 | AR23: 4.7 | AS23: 2.1 | AT23: 6.8 | AU23: 0.194 | AV23: 6 | AW23: 1.2 | AX23: 7.1 | AY23: 3.9 | AZ23: 6.95 | BA23: 0.15752549 | BB23: 0
A24: Bradley Beal | B24: 43279250 | C24: SG | D24: 29 | E24: WAS | F24: 50 | G24: 50 | H24: 33.5 | I24: 8.9 | J24: 17.6 | K24: 0.506 | L24: 1.6 | M24: 4.4 | N24: 0.365 | O24: 7.3 | P24: 13.2 | Q24: 0.552 | R24: 0.551 | S24: 3.8 | T24: 4.6 | U24: 0.842 | V24: 0.8 | W24: 3.1 | X24: 3.9 | Y24: 5.4 | Z24: 0.9 | AA24: 0.7 | AB24: 2.9 | AC24: 2.1 | AD24: 23.2 | AE24: 1673 | AF24: 19.7 | AG24: 0.593 | AH24: 0.249 | AI24: 0.26 | AJ24: 2.8 | AK24: 9.9 | AL24: 6.5 | AM24: 26.6 | AN24: 1.3 | AO24: 1.7 | AP24: 12.9 | AQ24: 29.2 | AR24: 2.2 | AS24: 1.2 | AT24: 3.4 | AU24: 0.099 | AV24: 2.9 | AW24: -1.2 | AX24: 1.8 | AY24: 1.6 | AZ24: 2.6 | BA24: 0.060074978 | BB24: 0
A25: Kawhi Leonard | B25: 42492492 | C25: SF | D25: 31 | E25: LAC | F25: 52 | G25: 50 | H25: 33.6 | I25: 8.6 | J25: 16.8 | K25: 0.512 | L25: 2 | M25: 4.8 | N25: 0.416 | O25: 6.6 | P25: 11.9 | Q25: 0.551 | R25: 0.572 | S25: 4.7 | T25: 5.4 | U25: 0.871 | V25: 1.1 | W25: 5.4 | X25: 6.5 | Y25: 3.9 | Z25: 1.4 | AA25: 0.5 | AB25: 1.7 | AC25: 1.6 | AD25: 23.8 | AE25: 1748 | AF25: 23.9 | AG25: 0.623 | AH25: 0.287 | AI25: 0.32 | AJ25: 3.7 | AK25: 17.8 | AL25: 10.8 | AM25: 19.6 | AN25: 2 | AO25: 1.4 | AP25: 8.1 | AQ25: 27 | AR25: 4.9 | AS25: 2.2 | AT25: 7.1 | AU25: 0.194 | AV25: 5.1 | AW25: 0.9 | AX25: 6.1 | AY25: 3.5 | AZ25: 6.6 | BA25: 0.15532156 | BB25: 0
A26: Paul George | B26: 42492492 | C26: SF | D26: 32 | E26: LAC | F26: 56 | G26: 56 | H26: 34.6 | I26: 8.2 | J26: 17.9 | K26: 0.457 | L26: 2.8 | M26: 7.6 | N26: 0.371 | O26: 5.4 | P26: 10.3 | Q26: 0.521 | R26: 0.536 | S26: 4.6 | T26: 5.3 | U26: 0.871 | V26: 0.8 | W26: 5.3 | X26: 6.1 | Y26: 5.1 | Z26: 1.5 | AA26: 0.4 | AB26: 3.1 | AC26: 2.8 | AD26: 23.8 | AE26: 1939 | AF26: 19.6 | AG26: 0.588 | AH26: 0.424 | AI26: 0.293 | AJ26: 2.6 | AK26: 17 | AL26: 9.9 | AM26: 24.2 | AN26: 2.1 | AO26: 0.9 | AP26: 13.4 | AQ26: 29.5 | AR26: 2.3 | AS26: 2.3 | AT26: 4.6 | AU26: 0.114 | AV26: 2.4 | AW26: 0.3 | AX26: 2.8 | AY26: 2.3 | AZ26: 3.7 | BA26: 0.087074206 | BB26: 0
A27: Giannis Antetokounmpo | B27: 42492492 | C27: PF | D27: 28 | E27: MIL | F27: 63 | G27: 63 | H27: 32.1 | I27: 11.2 | J27: 20.3 | K27: 0.553 | L27: 0.7 | M27: 2.7 | N27: 0.275 | O27: 10.5 | P27: 17.6 | Q27: 0.596 | R27: 0.572 | S27: 7.9 | T27: 12.3 | U27: 0.645 | V27: 2.2 | W27: 9.6 | X27: 11.8 | Y27: 5.7 | Z27: 0.8 | AA27: 0.8 | AB27: 3.9 | AC27: 3.1 | AD27: 31.1 | AE27: 2024 | AF27: 29 | AG27: 0.605 | AH27: 0.134 | AI27: 0.604 | AJ27: 7.3 | AK27: 30 | AL27: 19.1 | AM27: 33.2 | AN27: 1.2 | AO27: 2.1 | AP27: 13.2 | AQ27: 38.8 | AR27: 4.9 | AS27: 3.7 | AT27: 8.6 | AU27: 0.204 | AV27: 5.8 | AW27: 2.7 | AX27: 8.5 | AY27: 5.4 | AZ27: 8.55 | BA27: 0.20121202 | BB27: 0
A28: Damian Lillard | B28: 42492492 | C28: PG | D28: 32 | E28: POR | F28: 58 | G28: 58 | H28: 36.3 | I28: 9.6 | J28: 20.7 | K28: 0.463 | L28: 4.2 | M28: 11.3 | N28: 0.371 | O28: 5.4 | P28: 9.4 | Q28: 0.574 | R28: 0.564 | S28: 8.8 | T28: 9.6 | U28: 0.914 | V28: 0.8 | W28: 4 | X28: 4.8 | Y28: 7.3 | Z28: 0.9 | AA28: 0.3 | AB28: 3.3 | AC28: 1.9 | AD28: 32.2 | AE28: 2107 | AF28: 26.7 | AG28: 0.645 | AH28: 0.547 | AI28: 0.464 | AJ28: 2.4 | AK28: 12.8 | AL28: 7.6 | AM28: 35 | AN28: 1.2 | AO28: 0.8 | AP28: 11.7 | AQ28: 33.8 | AR28: 8.2 | AS28: 0.8 | AT28: 9 | AU28: 0.205 | AV28: 8.3 | AW28: -1.2 | AX28: 7.1 | AY28: 4.9 | AZ28: 8.05 | BA28: 0.18944523 | BB28: 0
A29: Klay Thompson | B29: 40600080 | C29: SF | D29: 32 | E29: GSW | F29: 69 | G29: 69 | H29: 33 | I29: 7.9 | J29: 18.1 | K29: 0.436 | L29: 4.4 | M29: 10.6 | N29: 0.412 | O29: 3.6 | P29: 7.6 | Q29: 0.47 | R29: 0.556 | S29: 1.7 | T29: 1.9 | U29: 0.879 | V29: 0.6 | W29: 3.6 | X29: 4.1 | Y29: 2.4 | Z29: 0.7 | AA29: 0.4 | AB29: 1.8 | AC29: 1.9 | AD29: 21.9 | AE29: 2279 | AF29: 14.7 | AG29: 0.576 | AH29: 0.584 | AI29: 0.105 | AJ29: 1.9 | AK29: 11.7 | AL29: 6.9 | AM29: 11 | AN29: 1 | AO29: 1.1 | AP29: 8.6 | AQ29: 26.4 | AR29: 1.2 | AS29: 1.9 | AT29: 3.1 | AU29: 0.066 | AV29: 1.5 | AW29: -1.7 | AX29: -0.3 | AY29: 1 | AZ29: 1.4 | BA29: 0.034482691 | BB29: 0
A30: Rudy Gobert | B30: 38172414 | C30: C | D30: 30 | E30: MIN | F30: 70 | G30: 70 | H30: 30.7 | I30: 5.1 | J30: 7.8 | K30: 0.659 | L30: 0 | M30: 0 | N30: 0 | O30: 5.1 | P30: 7.8 | Q30: 0.663 | R30: 0.659 | S30: 3.1 | T30: 4.9 | U30: 0.644 | V30: 3.3 | W30: 8.3 | X30: 11.6 | Y30: 1.2 | Z30: 0.8 | AA30: 1.4 | AB30: 1.7 | AC30: 3 | AD30: 13.4 | AE30: 2148 | AF30: 18.9 | AG30: 0.675 | AH30: 0.005 | AI30: 0.623 | AJ30: 12.2 | AK30: 29.8 | AL30: 21.2 | AM30: 5.6 | AN30: 1.2 | AO30: 3.9 | AP30: 14.9 | AQ30: 16.3 | AR30: 4.3 | AS30: 3.5 | AT30: 7.8 | AU30: 0.174 | AV30: 0 | AW30: 0.7 | AX30: 0.7 | AY30: 1.4 | AZ30: 4.25 | BA30: 0.11133695 | BB30: 0
A31: Anthony Davis | B31: 37980720 | C31: C | D31: 29 | E31: LAL | F31: 56 | G31: 54 | H31: 34 | I31: 9.7 | J31: 17.2 | K31: 0.563 | L31: 0.3 | M31: 1.3 | N31: 0.257 | O31: 9.3 | P31: 15.9 | Q31: 0.589 | R31: 0.573 | S31: 6.2 | T31: 7.9 | U31: 0.784 | V31: 3.5 | W31: 9.1 | X31: 12.5 | Y31: 2.6 | Z31: 1.1 | AA31: 2 | AB31: 2.2 | AC31: 2.6 | AD31: 25.9 | AE31: 1904 | AF31: 27.8 | AG31: 0.627 | AH31: 0.077 | AI31: 0.462 | AJ31: 11.3 | AK31: 27.6 | AL31: 19.7 | AM31: 13 | AN31: 1.5 | AO31: 5.1 | AP31: 9.5 | AQ31: 28.4 | AR31: 5.5 | AS31: 3.4 | AT31: 9 | AU31: 0.226 | AV31: 4.6 | AW31: 1.7 | AX31: 6.3 | AY31: 4 | AZ31: 7.65 | BA31: 0.20141798 | BB31: 0
... A83: Dejounte Murray | B83: 17071120 | C83: SG | D83: 26 | E83: ATL | F83: 74 | G83: 74 | H83: 36.4 | I83: 8.3 | J83: 17.8 | K83: 0.464 | L83: 1.8 | M83: 5.2 | N83: 0.344 | O83: 6.5 | P83: 12.6 | Q83: 0.514 | R83: 0.514 | S83: 2.1 | T83: 2.6 | U83: 0.832 | V83: 0.7 | W83: 4.5 | X83: 5.3 | Y83: 6.1 | Z83: 1.5 | AA83: 0.3 | AB83: 2.2 | AC83: 1.4 | AD83: 20.5 | AE83: 2693 | AF83: 17 | AG83: 0.54 | AH83: 0.293 | AI83: 0.144 | AJ83: 2.1 | AK83: 13.8 | AL83: 7.9 | AM83: 24 | AN83: 2 | AO83: 0.6 | AP83: 10.2 | AQ83: 24.4 | AR83: 2.4 | AS83: 2.3 | AT83: 4.7 | AU83: 0.084 | AV83: 1.1 | AW83: 0 | AX83: 1 | AY83: 2.1 | AZ83: 2.85 | BA83: 0.16694862 | BB83: 0
A84: Mitchell Robinson | B84: 17045454 | C84: C | D84: 24 | E84: NYK | F84: 59 | G84: 58 | H84: 27 | I84: 3.2 | J84: 4.7 | K84: 0.671 | L84: 0 | M84: 0 | O84: 3.2 | P84: 4.7 | Q84: 0.671 | R84: 0.671 | S84: 1 | T84: 2.1 | U84: 0.484 | V84: 4.5 | W84: 4.9 | X84: 9.4 | Y84: 0.9 | Z84: 0.9 | AA84: 1.8 | AB84: 0.7 | AC84: 2.7 | AD84: 7.4 | AE84: 1591 | AF84: 18.9 | AG84: 0.652 | AH84: 0 | AI84: 0.436 | AJ84: 18.4 | AK84: 20 | AL84: 19.2 | AM84: 4.5 | AN84: 1.7 | AO84: 6.5 | AP84: 10.9 | AQ84: 10.1 | AR84: 4 | AS84: 2.6 | AT84: 6.5 | AU84: 0.197 | AV84: 1 | AW84: 1.4 | AX84: 2.4 | AY84: 1.7 | AZ84: 4.45 | BA84: 0.26106668 | BB84: 0
A85: Norman Powell | B85: 16758621 | C85: SG | D85: 29 | E85: LAC | F85: 60 | G85: 8 | H85: 26.1 | I85: 5.7 | J85: 11.8 | K85: 0.479 | L85: 1.9 | M85: 4.8 | N85: 0.397 | O85: 3.8 | P85: 7.1 | Q85: 0.534 | R85: 0.559 | S85: 3.8 | T85: 4.6 | U85: 0.812 | V85: 0.4 | W85: 2.5 | X85: 2.9 | Y85: 1.8 | Z85: 0.8 | AA85: 0.3 | AB85: 1.7 | AC85: 2.1 | AD85: 17 | AE85: 1567 | AF85: 17.1 | AG85: 0.612 | AH85: 0.404 | AI85: 0.39 | AJ85: 1.7 | AK85: 10.7 | AL85: 6.3 | AM85: 11 | AN85: 1.6 | AO85: 1 | AP85: 10.8 | AQ85: 26 | AR85: 2.1 | AS85: 1.4 | AT85: 3.5 | AU85: 0.107 | AV85: 0.9 | AW85: -0.7 | AX85: 0.3 | AY85: 0.9 | AZ85: 1.9 | BA85: 0.11337448 | BB85: 0
A86: Collin Sexton | B86: 16700000 | C86: PG | D86: 24 | E86: UTA | F86: 48 | G86: 15 | H86: 23.9 | I86: 4.9 | J86: 9.8 | K86: 0.506 | L86: 1 | M86: 2.5 | N86: 0.393 | O86: 3.9 | P86: 7.2 | Q86: 0.546 | R86: 0.558 | S86: 3.4 | T86: 4.1 | U86: 0.819 | V86: 0.8 | W86: 1.4 | X86: 2.2 | Y86: 2.9 | Z86: 0.6 | AA86: 0.1 | AB86: 1.8 | AC86: 2.3 | AD86: 14.3 | AE86: 1145 | AF86: 15.9 | AG86: 0.616 | AH86: 0.261 | AI86: 0.425 | AJ86: 3.5 | AK86: 6.3 | AL86: 5 | AM86: 17.9 | AN86: 1.1 | AO86: 0.4 | AP86: 13.3 | AQ86: 23.4 | AR86: 2 | AS86: 0.5 | AT86: 2.5 | AU86: 0.105 | AV86: 0.1 | AW86: -1.5 | AX86: -1.3 | AY86: 0.2 | AZ86: 0.6 | BA86: 0.035928144 | BB86: 0
A87: Markelle Fultz | B87: 16500000 | C87: PG | D87: 24 | E87: ORL | F87: 60 | G87: 60 | H87: 29.6 | I87: 5.8 | J87: 11.3 | K87: 0.514 | L87: 0.5 | M87: 1.5 | N87: 0.31 | O87: 5.4 | P87: 9.9 | Q87: 0.544 | R87: 0.534 | S87: 1.9 | T87: 2.4 | U87: 0.783 | V87: 1.2 | W87: 2.8 | X87: 3.9 | Y87: 5.7 | Z87: 1.5 | AA87: 0.4 | AB87: 2.3 | AC87: 2.2 | AD87: 14 | AE87: 1778 | AF87: 16.6 | AG87: 0.564 | AH87: 0.128 | AI87: 0.211 | AJ87: 4.4 | AK87: 10.5 | AL87: 7.4 | AM87: 29.8 | AN87: 2.4 | AO87: 1.4 | AP87: 15.8 | AQ87: 21.3 | AR87: 1.7 | AS87: 2 | AT87: 3.7 | AU87: 0.1 | AV87: -0.1 | AW87: 0.7 | AX87: 0.5 | AY87: 1.2 | AZ87: 2.1 | BA87: 0.12727273 | BB87: 0
A88: Lauri Markkanen | B88: 16475454 | C88: PF | D88: 25 | E88: UTA | F88: 66 | G88: 66 | H88: 34.4 | I88: 8.7 | J88: 17.3 | K88: 0.499 | L88: 3 | M88: 7.7 | N88: 0.391 | O88: 5.6 | P88: 9.6 | Q88: 0.585 | R88: 0.586 | S88: 5.3 | T88: 6 | U88: 0.875 | V88: 2 | W88: 6.7 | X88: 8.6 | Y88: 1.9 | Z88: 0.6 | AA88: 0.6 | AB88: 1.9 | AC88: 2.1 | AD88: 25.6 | AE88: 2273 | AF88: 22.1 | AG88: 0.64 | AH88: 0.446 | AI88: 0.348 | AJ88: 6.3 | AK88: 20.7 | AL88: 13.6 | AM88: 8.6 | AN88: 0.9 | AO88: 1.4 | AP88: 8.8 | AQ88: 26.6 | AR88: 6.3 | AS88: 1.9 | AT88: 8.2 | AU88: 0.173 | AV88: 4.9 | AW88: -1 | AX88: 3.8 | AY88: 3.3 | AZ88: 6 | BA88: 0.36417813 | BB88: 0
A89: Marcus Morris | B89: 16372093 | C89: PF | D89: 33 | E89: LAC | F89: 65 | G89: 65 | H89: 28.1 | I89: 4.2 | J89: 9.9 | K89: 0.426 | L89: 1.7 | M89: 4.7 | N89: 0.364 | O89: 2.5 | P89: 5.2 | Q89: 0.484 | R89: 0.513 | S89: 1 | T89: 1.3 | U89: 0.782 | V89: 0.4 | W89: 3.5 | X89: 4 | Y89: 1.8 | Z89: 0.6 | AA89: 0.3 | AB89: 0.9 | AC89: 2.1 | AD89: 11.2 | AE89: 1825 | AF89: 10.5 | AG89: 0.534 | AH89: 0.479 | AI89: 0.135 | AJ89: 1.8 | AK89: 13.9 | AL89: 7.9 | AM89: 8.9 | AN89: 1.1 | AO89: 1 | AP89: 7.6 | AQ89: 17.6 | AR89: 0.4 | AS89: 1.6 | AT89: 2 | AU89: 0.053 | AV89: -1.8 | AW89: -0.2 | AX89: -1.9 | AY89: 0 | AZ89: 0.05 | BA89: 0.0030539773 | BB89: 0
A90: Tyus Jones | B90: 15000000 | C90: PG | D90: 26 | E90: MEM | F90: 80 | G90: 22 | H90: 24.3 | I90: 3.9 | J90: 8.9 | K90: 0.438 | L90: 1.5 | M90: 4.1 | N90: 0.371 | O90: 2.4 | P90: 4.8 | Q90: 0.495 | R90: 0.523 | S90: 1 | T90: 1.3 | U90: 0.8 | V90: 0.4 | W90: 2.2 | X90: 2.5 | Y90: 5.2 | Z90: 1 | AA90: 0.1 | AB90: 0.9 | AC90: 0.4 | AD90: 10.3 | AE90: 1940 | AF90: 16 | AG90: 0.546 | AH90: 0.459 | AI90: 0.141 | AJ90: 1.5 | AK90: 9.4 | AL90: 5.5 | AM90: 28.8 | AN90: 2 | AO90: 0.3 | AP90: 8.9 | AQ90: 17.7 | AR90: 3.4 | AS90: 2.3 | AT90: 5.7 | AU90: 0.141 | AV90: 1.2 | AW90: 0.3 | AX90: 1.6 | AY90: 1.7 | AZ90: 3.65 | BA90: 0.24333333 | BB90: 0
A91: Kevin Huerter | B91: 14508929 | C91: SG | D91: 24 | E91: SAC | F91: 75 | G91: 75 | H91: 29.4 | I91: 5.6 | J91: 11.5 | K91: 0.485 | L91: 2.7 | M91: 6.8 | N91: 0.402 | O91: 2.9 | P91: 4.7 | Q91: 0.604 | R91: 0.603 | S91: 1.3 | T91: 1.7 | U91: 0.725 | V91: 0.6 | W91: 2.8 | X91: 3.3 | Y91: 2.9 | Z91: 1.1 | AA91: 0.3 | AB91: 1.3 | AC91: 2.4 | AD91: 15.2 | AE91: 2203 | AF91: 15.2 | AG91: 0.617 | AH91: 0.589 | AI91: 0.151 | AJ91: 2.2 | AK91: 10.8 | AL91: 6.5 | AM91: 14.1 | AN91: 1.7 | AO91: 1 | AP91: 9.5 | AQ91: 19.9 | AR91: 3.3 | AS91: 1.7 | AT91: 4.9 | AU91: 0.107 | AV91: 1.4 | AW91: -0.3 | AX91: 1 | AY91: 1.7 | AZ91: 2.95 | BA91: 0.20332307 | BB91: 0
...

Sheet IP_RosterModel
A1: Player Name | B1: Salary | C1: Position | D1: Age | E1: Team | F1: GP | G1: GS | H1: MP | I1: FG | J1: FGA | K1: FG% | L1: 3P | M1: 3PA | N1: 3P% | O1: 2P | P1: 2PA | Q1: 2P% | R1: eFG% | S1: FT | T1: FTA | U1: FT% | V1: ORB | W1: DRB | X1: TRB | Y1: AST | Z1: STL | AA1: BLK | AB1: TOV | AC1: PF | AD1: PTS | AE1: Total Minutes | AF1: PER | AG1: TS% | AH1: 3PAr | AI1: FTr | AJ1: ORB% | AK1: DRB% | AL1: TRB% | AM1: AST% | AN1: STL% | AO1: BLK% | AP1: TOV% | AQ1: USG% | AR1: OWS | AS1: DWS | AT1: WS | AU1: WS/48 | AV1: OBPM | AW1: DBPM | AX1: BPM | AY1: VORP | AZ1: Score | BA1: Score_per_$M | BB1: Decision Variable | BD1: Total Score | BE1: Total Salary | BF1: Total Players | BG1: PG_Count | BH1: SG_Count | BI1: SF_Count | BJ1: PF_Count | BK1: C_Count | BL1: Cap | BM1: Roster Size
A2: Luka Doncic | B2: 37096500 | C2: PG | AT2: 12.1 | AX2: 8.2 | AZ2: 10.15 | BA2: 0.27361072 | BB2: 1 | BD2: =SUMPRODUCT(AZ2:AZ193, BB2:BB193) -> 67.75 | BE2: =SUMPRODUCT(B2:B193, BB2:BB193) -> 150708297 | BF2: =SUM(BB2:BB193) -> 12 | BG2: {=SUMPRODUCT(BB2:BB193, --(C2:C193="PG"))} -> 2 | BH2: {=SUMPRODUCT(BB2:BB193, --(C2:C193="SG"))} -> 3 | BI2: {=SUMPRODUCT(BB2:BB193, --(C2:C193="SF"))} -> 2 | BJ2: {=SUMPRODUCT(BB2:BB193, --(C2:C193="PF"))} -> 2 | BK2: {=SUMPRODUCT(BB2:BB193, --(C2:C193="C"))} -> 3 | BL2: =154000000 -> 154000000 | BM2: 12
A3: Domantas Sabonis | B3: 21100000 | C3: C | D3: 26 | E3: SAC | F3: 79 | G3: 79 | H3: 34.6 | I3: 7.3 | J3: 11.9 | K3: 0.615 | L3: 0.4 | M3: 1.1 | N3: 0.373 | O3: 6.9 | P3: 10.8 | Q3: 0.639 | R3: 0.632 | S3: 4.1 | T3: 5.5 | U3: 0.742 | V3: 3.2 | W3: 9.1 | X3: 12.3 | Y3: 7.3 | Z3: 0.8 | AA3: 0.5 | AB3: 2.9 | AC3: 3.5 | AD3: 19.1 | AE3: 2736 | AF3: 23.5 | AG3: 0.668 | AH3: 0.088 | AI3: 0.467 | AJ3: 10.6 | AK3: 30 | AL3: 20.3 | AM3: 30.4 | AN3: 1.1 | AO3: 1.2 | AP3: 16.9 | AQ3: 21.3 | AR3: 9.6 | AS3: 3 | AT3: 12.6 | AU3: 0.221 | AV3: 4.1 | AW3: 1.8 | AX3: 5.8 | AY3: 5.4 | AZ3: 9.2 | BA3: 0.43601896 | BB3: 1 | BL3: BB193 | BM3: = | BN3: 1 | BO3: Luka
A4: Tyrese Haliburton | B4: 4215120 | C4: PG | D4: 22 | E4: IND | F4: 56 | G4: 56 | H4: 33.6 | I4: 7.4 | J4: 15 | K4: 0.49 | L4: 2.9 | M4: 7.2 | N4: 0.4 | O4: 4.5 | P4: 7.8 | Q4: 0.572 | R4: 0.586 | S4: 3.1 | T4: 3.6 | U4: 0.871 | V4: 0.6 | W4: 3.1 | X4: 3.7 | Y4: 10.4 | Z4: 1.6 | AA4: 0.4 | AB4: 2.5 | AC4: 1.2 | AD4: 20.7 | AE4: 1883 | AF4: 23.6 | AG4: 0.624 | AH4: 0.478 | AI4: 0.239 | AJ4: 1.9 | AK4: 10.1 | AL4: 6 | AM4: 47.6 | AN4: 2.3 | AO4: 1.1 | AP4: 13.2 | AQ4: 23.8 | AR4: 6.4 | AS4: 1.2 | AT4: 7.6 | AU4: 0.195 | AV4: 7 | AW4: 0.2 | AX4: 7.2 | AY4: 4.4 | AZ4: 7.4 | BA4: 1.7555847 | BB4: 1 | BL4: BB26 | BM4: = | BN4: 1 | BO4: Kyrie
A5: Lauri Markkanen | B5: 16475454 | C5: PF | D5: 25 | E5: UTA | F5: 66 | G5: 66 | H5: 34.4 | I5: 8.7 | J5: 17.3 | K5: 0.499 | L5: 3 | M5: 7.7 | N5: 0.391 | O5: 5.6 | P5: 9.6 | Q5: 0.585 | R5: 0.586 | S5: 5.3 | T5: 6 | U5: 0.875 | V5: 2 | W5: 6.7 | X5: 8.6 | Y5: 1.9 | Z5: 0.6 | AA5: 0.6 | AB5: 1.9 | AC5: 2.1 | AD5: 25.6 | AE5: 2273 | AF5: 22.1 | AG5: 0.64 | AH5: 0.446 | AI5: 0.348 | AJ5: 6.3 | AK5: 20.7 | AL5: 13.6 | AM5: 8.6 | AN5: 0.9 | AO5: 1.4 | AP5: 8.8 | AQ5: 26.6 | AR5: 6.3 | AS5: 1.9 | AT5: 8.2 | AU5: 0.173 | AV5: 4.9 | AW5: -1 | AX5: 3.8 | AY5: 3.3 | AZ5: 6 | BA5: 0.36417813 | BB5: 1
A6: Kyrie Irving | B6: 38917057 | C6: SG | D6: 30 | E6: DAL | F6: 60 | G6: 60 | H6: 37.4 | I6: 9.9 | J6: 20.1 | K6: 0.494 | L6: 3.1 | M6: 8.3 | N6: 0.379 | O6: 6.8 | P6: 11.8 | Q6: 0.574 | R6: 0.572 | S6: 4.1 | T6: 4.6 | U6: 0.905 | V6: 1 | W6: 4.1 | X6: 5.1 | Y6: 5.5 | Z6: 1.1 | AA6: 0.8 | AB6: 2.1 | AC6: 2.8 | AD6: 27.1 | AE6: 2241 | AF6: 22.4 | AG6: 0.613 | AH6: 0.412 | AI6: 0.227 | AJ6: 3 | AK6: 12.3 | AL6: 7.7 | AM6: 25.4 | AN6: 1.4 | AO6: 1.7 | AP6: 8.8 | AQ6: 28.9 | AR6: 5.4 | AS6: 2 | AT6: 7.4 | AU6: 0.159 | AV6: 4.8 | AW6: -0.7 | AX6: 4.1 | AY6: 3.5 | AZ6: 5.75 | BA6: 0.14775012 | BB6: 1
A7: Kevon Looney | B7: 8000000 | C7: C | D7: 26 | E7: GSW | F7: 82 | G7: 70 | H7: 23.9 | I7: 3 | J7: 4.7 | K7: 0.63 | L7: 0 | M7: 0 | N7: 0 | O7: 3 | P7: 4.7 | Q7: 0.632 | R7: 0.63 | S7: 1.1 | T7: 1.9 | U7: 0.606 | V7: 3.3 | W7: 5.9 | X7: 9.3 | Y7: 2.5 | Z7: 0.6 | AA7: 0.6 | AB7: 0.5 | AC7: 2.7 | AD7: 7 | AE7: 1958 | AF7: 17.8 | AG7: 0.639 | AH7: 0.003 | AI7: 0.404 | AJ7: 15.7 | AK7: 26.8 | AL7: 21.4 | AM7: 13.8 | AN7: 1.3 | AO7: 2.2 | AP7: 9.1 | AQ7: 10.6 | AR7: 5.9 | AS7: 2.8 | AT7: 8.7 | AU7: 0.212 | AV7: 0.9 | AW7: 1.3 | AX7: 2.1 | AY7: 2 | AZ7: 5.4 | BA7: 0.675 | BB7: 1
A8: Evan Mobley | B8: 8478720 | C8: PF | D8: 21 | E8: CLE | F8: 79 | G8: 79 | H8: 34.4 | I8: 6.6 | J8: 12 | K8: 0.554 | L8: 0.3 | M8: 1.3 | N8: 0.216 | O8: 6.4 | P8: 10.7 | Q8: 0.595 | R8: 0.566 | S8: 2.6 | T8: 3.8 | U8: 0.674 | V8: 2.4 | W8: 6.6 | X8: 9 | Y8: 2.8 | Z8: 0.8 | AA8: 1.5 | AB8: 1.8 | AC8: 2.8 | AD8: 16.2 | AE8: 2715 | AF8: 17.9 | AG8: 0.591 | AH8: 0.108 | AI8: 0.321 | AJ8: 8.1 | AK8: 22.7 | AL8: 15.4 | AM8: 12.4 | AN8: 1.1 | AO8: 4 | AP8: 11.9 | AQ8: 20.2 | AR8: 3.7 | AS8: 4.8 | AT8: 8.5 | AU8: 0.151 | AV8: 0 | AW8: 1.6 | AX8: 1.7 | AY8: 2.5 | AZ8: 5.1 | BA8: 0.60150589 | BB8: 1
A9: Walker Kessler | B9: 2696400 | C9: C | D9: 21 | E9: UTA | F9: 74 | G9: 40 | H9: 23 | I9: 4 | J9: 5.6 | K9: 0.72 | L9: 0 | M9: 0 | N9: 0.333 | O9: 4 | P9: 5.6 | Q9: 0.723 | R9: 0.721 | S9: 1.1 | T9: 2.1 | U9: 0.516 | V9: 3.1 | W9: 5.3 | X9: 8.4 | Y9: 0.9 | Z9: 0.4 | AA9: 2.3 | AB9: 0.8 | AC9: 2.3 | AD9: 9.2 | AE9: 1703 | AF9: 21.5 | AG9: 0.702 | AH9: 0.007 | AI9: 0.384 | AJ9: 14.9 | AK9: 24.4 | AL9: 19.7 | AM9: 5.7 | AN9: 0.7 | AO9: 8.6 | AP9: 10.7 | AQ9: 13.3 | AR9: 4.6 | AS9: 2.5 | AT9: 7.1 | AU9: 0.2 | AV9: 1.4 | AW9: 1.5 | AX9: 2.9 | AY9: 2.1 | AZ9: 5 | BA9: 1.8543243 | BB9: 1
